Workbook

Sheet Справочник-не смотрим!
A1: Месяц | B1: февраль
A2: Год | B2: 2026

Sheet ЗАЯВКА-не смотрим!
A3: № п/п | B3: Наименование | C3: Ед. изм. | D3: ООТ №1 на 43 чел. | E3: ООТ №1 на 31 чел. | F3: ООТ №3 на 40 чел. | G3: ООТ №3 на 1 чел. (сах.д.) | H3: ООТ №3 на 62 чел. | I3: Отд. "Милосердие" на 58 чел. | J3: Отд. "Милосердие" на 17 чел. | K3: Отд. "Милосердие" на 4 чел., (сах.д.) | L3: Отд. "Милосердие" на 7 чел. | M3: ООТ №2 на 55 чел. | N3: ООТ №2 3 чел., (сах.д.) | O3: ООТ №2 на 19 чел. | P3: СРО на 92 чел. | Q3: СРО на 3 чел., (сах.д.) | R3: СРО на 14 чел. | S3: СРО на 32 чел. | T3: 16 отд ППБ на 1 чел. | U3: 16 отд ППБ на 8 чел. | V3: ИТОГО
A4: 1 | B4: Вода питьевая негазир. (5 л.) | C4: бут. | D4: ='1-П'!C52 -> 78 | E4: 62 | F4: 80 | G4: 2 | H4: 124 | I4: 116 | J4: 34 | K4: 8 | L4: 14 | M4: 110 | N4: 6 | O4: 38 | Q4: 6 | R4: 28 | S4: 64 | V4: =SUM(D4:U4) -> 770
A5: 2 | B5: Туалетная бумага "Набережные Челны" (рул.) | C5: шт. | D5: ='1-П'!D52 -> 39 | T5: 1 | U5: 16 | V5: =SUM(D5:U5) -> 56
A6: 3 | B6: Чай черный ГОСТ (100 гр.) | C6: упак. | D6: ='1-П'!C54 -> 0 | E6: 31 | F6: 40 | G6: 1 | H6: 62 | I6: 58 | J6: 17 | K6: 4 | L6: 7 | M6: 55 | N6: 3 | O6: 19 | Q6: 3 | R6: 14 | S6: 32 | T6: 1 | U6: 16 | V6: =SUM(D6:U6) -> 363
A7: 4 | B7: Чай черный пакетированный (25 пак.) | C7: упак. | D7: ='1-П'!C55 -> 0
A8: 5 | B8: Станки для бритья "Джилет Blue II Maximum" однораз. | C8: шт. | D8: ='1-П'!C56 -> член опекунской комиссии | E8: 155 | F8: 200 | G8: 5 | H8: 310 | I8: 290 | J8: 85 | K8: 20 | L8: 35 | M8: 275 | N8: 15 | O8: 95 | Q8: 15 | R8: 70 | S8: 160 | V8: =SUM(D8:U8) -> 1730
A9: 6 | B9: Говядина тушеная ж/б (325 гр. ключ) | C9: шт. | D9: ='1-П'!C57 -> 0 | G9: 1 | H9: 62 | J9: 17 | K9: 4 | M9: 55 | N9: 3 | Q9: 3 | S9: 32 | V9: =SUM(D9:U9) -> 177
A10: 7 | B10: Колбаса вареная "Докторская" ГОСТ (400 гр.) | C10: шт. | D10: ='1-П'!C58 -> 0 | F10: 40 | G10: 1 | H10: 62 | J10: 17 | K10: 4 | L10: 7 | M10: 55 | N10: 3 | O10: 19 | Q10: 3 | R10: 14 | S10: 32 | V10: =SUM(D10:U10) -> 257
A11: 8 | B11: Зефир Беково (белый, розовый, 250 гр.) | C11: упак. | D11: ='1-П'!C59 -> 0 | E11: 31 | F11: 40 | G11: 1 | H11: 62 | J11: 17 | K11: 4 | L11: 7 | M11: 55 | N11: 3 | O11: 19 | Q11: 3 | R11: 14 | S11: 32 | U11: 8 | V11: =SUM(D11:U11) -> 296
A12: 9 | B12: Ветчина в ассртименте ж/б (325 гр. ключ) | C12: шт. | D12: ='1-П'!C60 -> 0 | E12: 31 | F12: 40 | G12: 1 | H12: 62 | J12: 17 | K12: 4 | L12: 7 | M12: 55 | N12: 3 | O12: 19 | Q12: 3 | R12: 14 | S12: 32 | V12: =SUM(D12:U12) -> 288
A13: 10 | B13: Сыр в ассортименте (200 гр.) | C13: шт. | D13: ='1-П'!C61 -> 0 | E13: 31 | F13: 40 | G13: 1 | H13: 62 | J13: 17 | K13: 4 | L13: 7 | M13: 55 | N13: 3 | O13: 19 | Q13: 3 | R13: 14 | S13: 32 | T13: 1 | U13: 16 | V13: =SUM(D13:U13) -> 305
A14: 11 | B14: Вафли в ассортименте (200 гр.) | C14: упак. | D14: ='1-П'!C62 -> 0 | T14: 1 | U14: 8 | V14: =SUM(D14:U14) -> 9
A15: 12 | B15: Кофе растворимый черный в мягкой упаковке Monarch (150 г) | C15: шт. | D15: ='1-П'!C63 -> 0 | H15: 62 | J15: 17 | M15: 55 | S15: 32 | T15: 1 | U15: 16 | V15: =SUM(D15:U15) -> 183
A16: 13 | B16: Джем Махеевъ дой-пак 300 г в ассортименте | C16: шт. | D16: ='1-П'!C64 -> 0 | H16: 62 | I16: 58 | J16: 17 | M16: 55 | S16: 32 | V16: =SUM(D16:U16) -> 224
A17: 14 | B17: Колбаса в/к ГОСТ (400 гр.) | C17: шт. | D17: ='1-П'!C65 -> 0 | E17: 31 | H17: 62 | J17: 17 | M17: 55 | S17: 32 | V17: =SUM(D17:U17) -> 197
A18: 15 | B18: Шпроты в масле ж/б (160 гр., ключ) | C18: шт. | D18: ='1-П'!C66 -> 0 | U18: 8 | V18: =SUM(D18:U18) -> 8
A19: 16 | B19: Прияники с начинкой "Яшкино" 250 гр. | C19: упак. | D19: ='1-П'!C67 -> 0 | E19: 31 | F19: 40 | H19: 62 | I19: 58 | J19: 17 | L19: 7 | M19: 55 | O19: 19 | R19: 14 | S19: 32 | V19: =SUM(D19:U19) -> 335
A20: 17 | B20: Мини - рулеты (175 гр.) | C20: упак. | D20: ='1-П'!C68 -> 0 | E20: 31 | F20: 40 | H20: 62 | I20: 58 | J20: 17 | L20: 7 | M20: 55 | O20: 19 | R20: 14 | S20: 32 | V20: =SUM(D20:U20) -> 335
A21: 18 | B21: Мыло хозяйственное 72% (200 гр.) | C21: шт. | D21: ='1-П'!C69 -> 0 | E21: 31 | F21: 40 | G21: 1 | H21: 62 | I21: 58 | J21: 17 | K21: 4 | L21: 7 | M21: 55 | N21: 3 | O21: 19 | P21: 92 | V21: =SUM(D21:U21) -> 389
A22: 19 | B22: Конфеты шоколадные фасованные в ассортименте (250 гр.) | C22: упак. | D22: ='1-П'!C70 -> 0 | H22: 62 | J22: 17 | M22: 55 | S22: 32 | U22: 8 | V22: =SUM(D22:U22) -> 174
A23: 20 | B23: Печенье сахарное фасованное (200гр.) | C23: упак. | D23: ='1-П'!C71 -> 0 | H23: 62 | J23: 17 | M23: 55 | S23: 32 | V23: =SUM(D23:U23) -> 166
A24: 21 | B24: Консервы рыбные в ассортименте ж/б (230 гр., ключ) | C24: шт. | D24: ='1-П'!C72 -> 0 | E24: 31 | F24: 40 | G24: 1 | H24: 62 | J24: 17 | K24: 4 | L24: 7 | M24: 55 | N24: 3 | O24: 19 | Q24: 3 | R24: 14 | S24: 32 | V24: =SUM(D24:U24) -> 288
A25: 22 | B25: Освежитель воздуха (200 мл.) | C25: шт. | D25: ='1-П'!C73 -> 0 | H25: 62 | I25: 58 | J25: 17 | M25: 55 | S25: 32 | V25: =SUM(D25:U25) -> 224
A26: 23 | B26: Жидкое мыло (200 мл.) | C26: шт. | D26: ='1-П'!C74 -> 0 | G26: 1 | H26: 62 | I26: 58 | J26: 17 | K26: 4 | M26: 55 | N26: 3 | Q26: 3 | S26: 32 | V26: =SUM(D26:U26) -> 235
A27: 24 | B27: Лукум Беково (250 гр.) | C27: упак. | D27: ='1-П'!C75 -> 0 | G27: 1 | K27: 4 | N27: 3 | Q27: 3 | V27: =SUM(D27:U27) -> 11
A28: 25 | B28: Мармелад диабетический на фруктозе (200гр.) | C28: упак. | D28: ='1-П'!C76 -> 0 | G28: 1 | K28: 4 | N28: 3 | Q28: 3 | V28: =SUM(D28:U28) -> 11
A29: 26 | B29: Конфеты диабетические (200 гр.) | C29: упак. | D29: ='1-П'!C77 -> 0 | G29: 1 | K29: 4 | N29: 3 | Q29: 3 | V29: =SUM(D29:U29) -> 11
A30: 27 | B30: Паштет "Знаток" ж/б (250 гр., ключ) | C30: шт. | D30: ='1-П'!C78 -> 0 | G30: 1 | K30: 4 | N30: 3 | Q30: 3 | V30: =SUM(D30:U30) -> 11
A31: 28 | B31: Печенье диабетическое "Мария" (250гр.) | C31: упак. | D31: ='1-П'!C79 -> 0 | G31: 1 | K31: 4 | N31: 3 | Q31: 3 | V31: =SUM(D31:U31) -> 11
A32: 29 | B32: Крекер соленый (180 гр.) | C32: упак. | D32: ='1-П'!C80 -> 0 | G32: 1 | K32: 4 | N32: 3 | Q32: 3 | V32: =SUM(D32:U32) -> 11
A33: 30 | B33: Печенье детское Бонди Бегемотик (180 гр.) | C33: упак. | D33: ='1-П'!C81 -> 0 | I33: 58 | V33: =SUM(D33:U33) -> 58
A34: 31 | B34: Килька Балтийская в томтном соусе 240 г ключ | C34: шт. | D34: ='1-П'!C82 -> 0 | I34: 58 | V34: =SUM(D34:U34) -> 58
A35: 32 | B35: Паштет HAME из гусиной печени (105 гр.) | C35: шт. | D35: ='1-П'!C83 -> 0 | I35: 58 | V35: =SUM(D35:U35) -> 58
A36: 33 | B36: Паштет HAME с мясом птицы (105 гр.) | C36: шт. | D36: ='1-П'!C84 -> 0 | I36: 58 | V36: =SUM(D36:U36) -> 58
A37: 34 | B37: Паштет HAME с мясом индейки (105 гр.) | C37: шт. | D37: ='1-П'!C85 -> 0 | I37: 58 | V37: =SUM(D37:U37) -> 58
A38: 35 | B38: Мини - кексы (250 гр.) | C38: упак. | D38: ='1-П'!C86 -> 0 | I38: 58 | U38: 8 | V38: =SUM(D38:U38) -> 66
A39: 36 | B39: Сыр плавленный "Вкуснотеево" (ванночка, 200 гр.) | C39: шт. | D39: ='1-П'!C87 -> 0 | I39: 58 | V39: =SUM(D39:U39) -> 58
A40: 37 | B40: Зефир в шоколаде Беково (250 гр.) | C40: упак. | D40: ='1-П'!C88 -> 0 | I40: 58 | V40: =SUM(D40:U40) -> 58
A41: 38 | B41: Сахар рафинад (500 гр.) | C41: упак. | D41: ='1-П'!C89 -> 0 | T41: 1 | U41: 8 | V41: =SUM(D41:U41) -> 9
A42: 39 | B42: Сок в ассортименте (1 л.) | C42: шт. | D42: ='1-П'!C90 -> 0 | T42: 1 | U42: 8 | V42: =SUM(D42:U42) -> 9
...

Sheet Сводная ведомость
A10: СВОДНАЯ ВЕДОМОСТЬ
A11: на обеспечение продуктами питания и средствами личной гигиены за счет личных средств получателей социальных услуг
A12: ГАУСО ПО «Сосновский психоневрологический интернат»
R13: на | S13: ='Справочник-не смотрим!'!B1 -> февраль | U13: ='Справочник-не смотрим!'!B2 -> 2026 | W13: года.
A15: № п/п | B15: Наименование отделения | C15: Количество ПСУ | D15: Наименование товара
D16: ='ЗАЯВКА-не смотрим!'!B4 -> Вода питьевая негазир. (5 л.) | E16: ='ЗАЯВКА-не смотрим!'!B5 -> Туалетная бумага "Набережные Челны" (рул.) | F16: ='ЗАЯВКА-не смотрим!'!B6 -> Чай черный ГОСТ (100 гр.) | G16: ='ЗАЯВКА-не смотрим!'!B7 -> Чай черный пакетированный (25 пак.) | H16: ='ЗАЯВКА-не смотрим!'!B8 -> Станки для бритья "Джилет Blue II Maximum" однораз. | I16: ='ЗАЯВКА-не смотрим!'!B9 -> Говядина тушеная ж/б (325 гр. ключ) | J16: ='ЗАЯВКА-не смотрим!'!B10 -> Колбаса вареная "Докторская" ГОСТ (400 гр.) | K16: ='ЗАЯВКА-не смотрим!'!B11 -> Зефир Беково (белый, розовый, 250 гр.) | L16: ='ЗАЯВКА-не смотрим!'!B12 -> Ветчина в ассртименте ж/б (325 гр. ключ) | M16: ='ЗАЯВКА-не смотрим!'!B13 -> Сыр в ассортименте (200 гр.) | N16: ='ЗАЯВКА-не смотрим!'!B14 -> Вафли в ассортименте (200 гр.) | O16: ='ЗАЯВКА-не смотрим!'!B15 -> Кофе растворимый черный в мягкой упаковке Monarch (150 г) | P16: ='ЗАЯВКА-не смотрим!'!B16 -> Джем Махеевъ дой-пак 300 г в ассортименте | Q16: ='ЗАЯВКА-не смотрим!'!B17 -> Колбаса в/к ГОСТ (400 гр.) | R16: ='ЗАЯВКА-не смотрим!'!B18 -> Шпроты в масле ж/б (160 гр., ключ) | S16: ='ЗАЯВКА-не смотрим!'!B19 -> Прияники с начинкой "Яшкино" 250 гр. | T16: ='ЗАЯВКА-не смотрим!'!B20 -> Мини - рулеты (175 гр.) | U16: ='ЗАЯВКА-не смотрим!'!B21 -> Мыло хозяйственное 72% (200 гр.) | V16: ='ЗАЯВКА-не смотрим!'!B22 -> Конфеты шоколадные фасованные в ассортименте (250 гр.) | W16: ='ЗАЯВКА-не смотрим!'!B23 -> Печенье сахарное фасованное (200гр.) | X16: ='ЗАЯВКА-не смотрим!'!B24 -> Консервы рыбные в ассортименте ж/б (230 гр., ключ) | Y16: ='ЗАЯВКА-не смотрим!'!B25 -> Освежитель воздуха (200 мл.) | Z16: ='ЗАЯВКА-не смотрим!'!B26 -> Жидкое мыло (200 мл.) | AA16: ='ЗАЯВКА-не смотрим!'!B27 -> Лукум Беково (250 гр.) | AB16: ='ЗАЯВКА-не смотрим!'!B28 -> Мармелад диабетический на фруктозе (200гр.) | AC16: ='ЗАЯВКА-не смотрим!'!B29 -> Конфеты диабетические (200 гр.) | AD16: ='ЗАЯВКА-не смотрим!'!B30 -> Паштет "Знаток" ж/б (250 гр., ключ) | AE16: ='ЗАЯВКА-не смотрим!'!B31 -> Печенье диабетическое "Мария" (250гр.) | AF16: ='ЗАЯВКА-не смотрим!'!B32 -> Крекер соленый (180 гр.) | AG16: ='ЗАЯВКА-не смотрим!'!B33 -> Печенье детское Бонди Бегемотик (180 гр.) | AH16: ='ЗАЯВКА-не смотрим!'!B34 -> Килька Балтийская в томтном соусе 240 г ключ | AI16: ='ЗАЯВКА-не смотрим!'!B35 -> Паштет HAME из гусиной печени (105 гр.) | AJ16: ='ЗАЯВКА-не смотрим!'!B36 -> Паштет HAME с мясом птицы (105 гр.) | AK16: ='ЗАЯВКА-не смотрим!'!B37 -> Паштет HAME с мясом индейки (105 гр.) | AL16: ='ЗАЯВКА-не смотрим!'!B38 -> Мини - кексы (250 гр.) | AM16: ='ЗАЯВКА-не смотрим!'!B39 -> Сыр плавленный "Вкуснотеево" (ванночка, 200 гр.) | AN16: ='ЗАЯВКА-не смотрим!'!B40 -> Зефир в шоколаде Беково (250 гр.) | AO16: ='ЗАЯВКА-не смотрим!'!B41 -> Сахар рафинад (500 гр.) | AP16: ='ЗАЯВКА-не смотрим!'!B42 -> Сок в ассортименте (1 л.) | AQ16: ='ЗАЯВКА-не смотрим!'!B43 -> Пена для бритья "АРКО" (200мл) | AR16: ='ЗАЯВКА-не смотрим!'!B44 -> Сигареты с фильтром в пачке (20 сигарет) | AS16: ='ЗАЯВКА-не смотрим!'!B45 -> Туалетная вода, 200 мл | AT16: ='ЗАЯВКА-не смотрим!'!B46 -> Зажигалка
C17: чел. | D17: ='ЗАЯВКА-не смотрим!'!C4 -> бут. | E17: ='ЗАЯВКА-не смотрим!'!C5 -> шт. | F17: ='ЗАЯВКА-не смотрим!'!C6 -> упак. | G17: ='ЗАЯВКА-не смотрим!'!C7 -> упак. | H17: ='ЗАЯВКА-не смотрим!'!C8 -> шт. | I17: ='ЗАЯВКА-не смотрим!'!C9 -> шт. | J17: ='ЗАЯВКА-не смотрим!'!C10 -> шт. | K17: ='ЗАЯВКА-не смотрим!'!C11 -> упак. | L17: ='ЗАЯВКА-не смотрим!'!C12 -> шт. | M17: ='ЗАЯВКА-не смотрим!'!C13 -> шт. | N17: ='ЗАЯВКА-не смотрим!'!C14 -> упак. | O17: ='ЗАЯВКА-не смотрим!'!C15 -> шт. | P17: ='ЗАЯВКА-не смотрим!'!C16 -> шт. | Q17: ='ЗАЯВКА-не смотрим!'!C17 -> шт. | R17: ='ЗАЯВКА-не смотрим!'!C18 -> шт. | S17: ='ЗАЯВКА-не смотрим!'!C19 -> упак. | T17: ='ЗАЯВКА-не смотрим!'!C20 -> упак. | U17: ='ЗАЯВКА-не смотрим!'!C21 -> шт. | V17: ='ЗАЯВКА-не смотрим!'!C22 -> упак. | W17: ='ЗАЯВКА-не смотрим!'!C23 -> упак. | X17: ='ЗАЯВКА-не смотрим!'!C24 -> шт. | Y17: ='ЗАЯВКА-не смотрим!'!C25 -> шт. | Z17: ='ЗАЯВКА-не смотрим!'!C26 -> шт. | AA17: ='ЗАЯВКА-не смотрим!'!C27 -> упак. | AB17: ='ЗАЯВКА-не смотрим!'!C28 -> упак. | AC17: ='ЗАЯВКА-не смотрим!'!C29 -> упак. | AD17: ='ЗАЯВКА-не смотрим!'!C30 -> шт. | AE17: ='ЗАЯВКА-не смотрим!'!C31 -> упак. | AF17: ='ЗАЯВКА-не смотрим!'!C32 -> упак. | AG17: ='ЗАЯВКА-не смотрим!'!C33 -> упак. | AH17: ='ЗАЯВКА-не смотрим!'!C34 -> шт. | AI17: ='ЗАЯВКА-не смотрим!'!C35 -> шт. | AJ17: ='ЗАЯВКА-не смотрим!'!C36 -> шт. | AK17: ='ЗАЯВКА-не смотрим!'!C37 -> шт. | AL17: ='ЗАЯВКА-не смотрим!'!C38 -> упак. | AM17: ='ЗАЯВКА-не смотрим!'!C39 -> шт. | AN17: ='ЗАЯВКА-не смотрим!'!C40 -> упак. | AO17: ='ЗАЯВКА-не смотрим!'!C41 -> упак. | AP17: ='ЗАЯВКА-не смотрим!'!C42 -> шт. | AQ17: ='ЗАЯВКА-не смотрим!'!C43 -> шт. | AR17: ='ЗАЯВКА-не смотрим!'!C44 -> пач. | AS17: ='ЗАЯВКА-не смотрим!'!C45 -> шт. | AT17: ='ЗАЯВКА-не смотрим!'!C46 -> шт.
A18: 1 | B18: Отд. общего типа №1 (полный) | C18: =COUNTA('1-П'!B13:B51) -> 39 | D18: ='1-П'!C52 -> 78 | E18: ='1-П'!D52 -> 39 | F18: ='1-П'!E52 -> 39 | G18: ='1-П'!F52 -> 0 | H18: ='1-П'!G52 -> 195 | I18: ='1-П'!H52 -> 39 | J18: ='1-П'!I52 -> 39 | K18: ='1-П'!J52 -> 0 | ... AT18: ='1-П'!AS52 -> 0
A19: 2 | B19: Отд. общего типа №1 (сокращенный) | C19: =COUNTA('1-С'!B17:B54) -> 38 | D19: ='1-С'!C55 -> 76 | E19: ='1-С'!D55 -> 38 | F19: ='1-С'!E55 -> 38 | G19: ='1-С'!F55 -> 0 | H19: ='1-С'!G55 -> 190 | I19: ='1-С'!H55 -> 38 | J19: ='1-С'!I55 -> 38 | K19: ='1-С'!J55 -> 0 | ... AT19: ='1-С'!AS55 -> 0
A20: 3 | B20: Отд. общего типа №2 (полный) | C20: =COUNTA('2-П'!B17:B78) -> 62 | D20: ='2-П'!C79 -> 124 | E20: ='2-П'!D79 -> 62 | F20: ='2-П'!E79 -> 0 | G20: ='2-П'!F79 -> 0 | H20: ='2-П'!G79 -> 310 | I20: ='2-П'!H79 -> 62 | J20: ='2-П'!I79 -> 62 | K20: ='2-П'!J79 -> 0 | ... AT20: ='2-П'!AS79 -> 0
A21: 4 | B21: Отд. общего типа №2 (сокращенный) | C21: =COUNTA('2-С'!B17:B47) -> 31 | D21: ='2-С'!C48 -> 60 | E21: ='2-С'!D48 -> 30 | F21: ='2-С'!E48 -> 0 | G21: ='2-С'!F48 -> 0 | H21: ='2-С'!G48 -> 150 | I21: ='2-С'!H48 -> 30 | J21: ='2-С'!I48 -> 30 | K21: ='2-С'!J48 -> 0 | ... AT21: ='2-С'!AS48 -> 0
A22: 5 | B22: Отд. общего типа №2 (сах. диабет) | C22: =COUNTA('2-СД'!B17:B19) -> 3 | D22: ='2-СД'!C20 -> 6 | E22: ='2-СД'!D20 -> 3 | F22: ='2-СД'!E20 -> 0 | G22: ='2-СД'!F20 -> 0 | H22: ='2-СД'!G20 -> 15 | I22: ='2-СД'!H20 -> 3 | J22: ='2-СД'!I20 -> 3 | K22: ='2-СД'!J20 -> 0 | ... AT22: ='2-СД'!AS20 -> 0
A23: 6 | B23: Отд. общего типа №3 (полный) | C23: =COUNTA('3-П'!B17:B68) -> 52 | D23: ='3-П'!C69 -> 100 | E23: ='3-П'!D69 -> 50 | F23: ='3-П'!E69 -> 50 | G23: ='3-П'!F69 -> 0 | H23: ='3-П'!G69 -> 250 | I23: ='3-П'!H69 -> 50 | J23: ='3-П'!I69 -> 50 | K23: ='3-П'!J69 -> 0 | ... AT23: ='3-П'!AS69 -> 45
A24: 7 | B24: Отд. общего типа №3 (сокращенный) | C24: =COUNTA('3-С'!B17:B68) -> 52 | D24: ='3-С'!C69 -> 92 | E24: ='3-С'!D69 -> 46 | F24: ='3-С'!E69 -> 46 | G24: ='3-С'!F69 -> 0 | H24: ='3-С'!G69 -> 230 | I24: ='3-С'!H69 -> 46 | J24: ='3-С'!I69 -> 46 | K24: ='3-С'!J69 -> 0 | ... AT24: ='3-С'!AS69 -> 51
A25: 8 | B25: Отд. общего типа №3 (сах. диабет) | C25: =COUNTA('3-СД'!B17:B18) -> 2 | D25: ='3-СД'!C19 -> 4 | E25: ='3-СД'!D19 -> 2 | F25: ='3-СД'!E19 -> 0 | G25: ='3-СД'!F19 -> 0 | H25: ='3-СД'!G19 -> 0 | I25: ='3-СД'!H19 -> 2 | J25: ='3-СД'!I19 -> 2 | K25: ='3-СД'!J19 -> 0 | ... AT25: ='3-СД'!AS19 -> 0
A26: 9 | B26: Соц.-реабилитац отд. (полный) | C26: =COUNTA('СРО-П'!B17:B50) -> 34 | D26: ='СРО-П'!C51 -> 68 | E26: ='СРО-П'!D51 -> 34 | F26: ='СРО-П'!E51 -> 34 | G26: ='СРО-П'!F51 -> 0 | H26: ='СРО-П'!G51 -> 170 | I26: ='СРО-П'!H51 -> 34 | J26: ='СРО-П'!I51 -> 34 | K26: ='СРО-П'!J51 -> 0 | ... AT26: ='СРО-П'!AS51 -> 0
A27: 10 | B27: Соц.-реабилитац отд. (сокращенный) | C27: =COUNTA('СРО-С'!B17:B45) -> 29 | D27: ='СРО-С'!C46 -> 58 | E27: ='СРО-С'!D46 -> 29 | F27: ='СРО-С'!E46 -> 29 | G27: ='СРО-С'!F46 -> 0 | H27: ='СРО-С'!G46 -> 145 | I27: ='СРО-С'!H46 -> 29 | J27: ='СРО-С'!I46 -> 29 | K27: ='СРО-С'!J46 -> 0 | ... AT27: ='СРО-С'!AS46 -> 0
A28: 11 | B28: Соц.-реабилитац отд. (сах. диабет) | C28: =COUNTA('СРО-СД'!B17:B19) -> 3 | D28: ='СРО-СД'!C20 -> 6 | E28: ='СРО-СД'!D20 -> 3 | F28: ='СРО-СД'!E20 -> 3 | G28: ='СРО-СД'!F20 -> 0 | H28: ='СРО-СД'!G20 -> 15 | I28: ='СРО-СД'!H20 -> 3 | J28: ='СРО-СД'!I20 -> 3 | K28: ='СРО-СД'!J20 -> 0 | ... AT28: ='СРО-СД'!AS20 -> 0
A29: 12 | B29: Отд. «Милосердие» (щадящее питание) | C29: =COUNTA('ОМ-ЩП'!B17:B64) -> 48 | D29: ='ОМ-ЩП'!C65 -> 96 | E29: ='ОМ-ЩП'!D65 -> 48 | F29: ='ОМ-ЩП'!E65 -> 48 | G29: ='ОМ-ЩП'!F65 -> 0 | H29: ='ОМ-ЩП'!G65 -> 240 | I29: ='ОМ-ЩП'!H65 -> 0 | J29: ='ОМ-ЩП'!I65 -> 0 | K29: ='ОМ-ЩП'!J65 -> 0 | ... AT29: ='ОМ-ЩП'!AS65 -> 0
A30: 13 | B30: Отд. «Милосердие» (полный) | C30: =COUNTA('ОМ-П'!B17:B40) -> 24 | D30: ='ОМ-П'!C41 -> 48 | E30: ='ОМ-П'!D41 -> 24 | F30: ='ОМ-П'!E41 -> 24 | G30: ='ОМ-П'!F41 -> 0 | H30: ='ОМ-П'!G41 -> 120 | I30: ='ОМ-П'!H41 -> 24 | J30: ='ОМ-П'!I41 -> 24 | K30: ='ОМ-П'!J41 -> 0 | ... AT30: ='ОМ-П'!AS41 -> 0
A31: 14 | B31: Отд. «Милосердие» (сокращенный) | C31: =COUNTA('ОМ-С'!B17:B28) -> 12 | D31: ='ОМ-С'!C29 -> 24 | E31: ='ОМ-С'!D29 -> 12 | F31: ='ОМ-С'!E29 -> 12 | G31: ='ОМ-С'!F29 -> 0 | H31: ='ОМ-С'!G29 -> 60 | I31: ='ОМ-С'!H29 -> 12 | J31: ='ОМ-С'!I29 -> 12 | K31: ='ОМ-С'!J29 -> 0 | ... AT31: ='ОМ-С'!AS29 -> 0
A32: 15 | B32: Отд. «Милосердие» (сах. диабет) | C32: =COUNTA('ОМ-СД'!B17:B20) -> 4 | D32: ='ОМ-СД'!C21 -> 8 | E32: ='ОМ-СД'!D21 -> 4 | F32: ='ОМ-СД'!E21 -> 4 | G32: ='ОМ-СД'!F21 -> 0 | H32: ='ОМ-СД'!G21 -> 20 | I32: ='ОМ-СД'!H21 -> 4 | J32: ='ОМ-СД'!I21 -> 4 | K32: ='ОМ-СД'!J21 -> 0 | ... AT32: ='ОМ-СД'!AS21 -> 0
A33: 16 | B33: 16 отд ППБ (полный) | C33: =COUNTA('ППБ-П'!B17:B22) -> 6 | D33: ='ППБ-П'!C23 -> 0 | E33: ='ППБ-П'!D23 -> 12 | F33: ='ППБ-П'!E23 -> 0 | G33: ='ППБ-П'!F23 -> 12 | H33: ='ППБ-П'!G23 -> 0 | I33: ='ППБ-П'!H23 -> 0 | J33: ='ППБ-П'!I23 -> 12 | K33: ='ППБ-П'!J23 -> 6 | ... AT33: ='ППБ-П'!AS23 -> 10
A34: 17 | B34: 16 отд ППБ (сокращенный) | C34: 0 | D34: ='ППБ-С'!C17 -> 0 | E34: ='ППБ-С'!D17 -> 0 | F34: ='ППБ-С'!E17 -> 0 | G34: ='ППБ-С'!F17 -> 0 | H34: ='ППБ-С'!G17 -> 0 | I34: ='ППБ-С'!H17 -> 0 | J34: ='ППБ-С'!I17 -> 0 | K34: ='ППБ-С'!J17 -> 0 | ... AT34: ='ППБ-С'!AS17 -> 0
B35: ИТОГО | C35: =SUM(C18:C34) -> 439 | D35: =SUM(D18:D33) -> 848 | E35: =SUM(E18:E33) -> 436 | F35: =SUM(F18:F33) -> 327 | G35: =SUM(G18:G33) -> 12 | H35: =SUM(H18:H33) -> 2110 | I35: =SUM(I18:I33) -> 376 | J35: =SUM(J18:J33) -> 388 | K35: =SUM(K18:K33) -> 6 | ... AT35: =SUM(AT18:AT33) -> 106

Sheet 1-П
A6: ЗАЯВКА
A7: на обеспечение продуктами питания и средствами личной гигиены за счет личных средств ПСУ отделения общего типа № 1
R8: на | S8: ='Справочник-не смотрим!'!B1 -> февраль | U8: ='Справочник-не смотрим!'!B2 -> 2026 | W8: года.
A10: № п/п | B10: ФИО | C10: Наименование товара
C11: ='Сводная ведомость'!D16 -> Вода питьевая негазир. (5 л.) | D11: ='Сводная ведомость'!E16 -> Туалетная бумага "Набережные Челны" (рул.) | E11: ='Сводная ведомость'!F16 -> Чай черный ГОСТ (100 гр.) | F11: ='Сводная ведомость'!G16 -> Чай черный пакетированный (25 пак.) | G11: ='Сводная ведомость'!H16 -> Станки для бритья "Джилет Blue II Maximum" однораз. | H11: ='Сводная ведомость'!I16 -> Говядина тушеная ж/б (325 гр. ключ) | I11: ='Сводная ведомость'!J16 -> Колбаса вареная "Докторская" ГОСТ (400 гр.) | J11: ='Сводная ведомость'!K16 -> Зефир Беково (белый, розовый, 250 гр.) | ... AS11: ='Сводная ведомость'!AT16 -> Зажигалка
C12: ='[1]ЗАЯВКА-не смотрим!'!C4 -> бут. | D12: ='[1]ЗАЯВКА-не смотрим!'!C5 -> шт. | E12: ='[1]ЗАЯВКА-не смотрим!'!C6 -> упак. | F12: ='[1]ЗАЯВКА-не смотрим!'!C7 -> упак. | G12: ='[1]ЗАЯВКА-не смотрим!'!C8 -> шт. | H12: ='[1]ЗАЯВКА-не смотрим!'!C9 -> шт. | I12: ='[1]ЗАЯВКА-не смотрим!'!C10 -> шт. | J12: ='[1]ЗАЯВКА-не смотрим!'!C11 -> упак. | K12: ='[1]ЗАЯВКА-не смотрим!'!C12 -> шт. | L12: ='[1]ЗАЯВКА-не смотрим!'!C13 -> шт. | M12: ='[1]ЗАЯВКА-не смотрим!'!C14 -> упак. | N12: ='[1]ЗАЯВКА-не смотрим!'!C15 -> шт. | O12: ='[1]ЗАЯВКА-не смотрим!'!C16 -> шт. | P12: ='[1]ЗАЯВКА-не смотрим!'!C17 -> шт. | Q12: ='[1]ЗАЯВКА-не смотрим!'!C18 -> шт. | R12: ='[1]ЗАЯВКА-не смотрим!'!C19 -> упак. | S12: ='[1]ЗАЯВКА-не смотрим!'!C20 -> упак. | T12: ='[1]ЗАЯВКА-не смотрим!'!C21 -> шт. | U12: ='[1]ЗАЯВКА-не смотрим!'!C22 -> упак. | V12: ='[1]ЗАЯВКА-не смотрим!'!C23 -> упак. | W12: ='[1]ЗАЯВКА-не смотрим!'!C24 -> шт. | X12: ='[1]ЗАЯВКА-не смотрим!'!C25 -> шт. | Y12: ='[1]ЗАЯВКА-не смотрим!'!C26 -> шт. | Z12: ='[1]ЗАЯВКА-не смотрим!'!C27 -> упак. | AA12: ='[1]ЗАЯВКА-не смотрим!'!C28 -> упак. | AB12: ='[1]ЗАЯВКА-не смотрим!'!C29 -> упак. | AC12: ='[1]ЗАЯВКА-не смотрим!'!C30 -> шт. | AD12: ='[1]ЗАЯВКА-не смотрим!'!C31 -> упак. | AE12: ='[1]ЗАЯВКА-не смотрим!'!C32 -> упак. | AF12: ='[1]ЗАЯВКА-не смотрим!'!C33 -> упак. | AG12: ='[1]ЗАЯВКА-не смотрим!'!C34 -> шт. | AH12: ='[1]ЗАЯВКА-не смотрим!'!C35 -> шт. | AI12: ='[1]ЗАЯВКА-не смотрим!'!C36 -> шт. | AJ12: ='[1]ЗАЯВКА-не смотрим!'!C37 -> шт. | AK12: ='[1]ЗАЯВКА-не смотрим!'!C38 -> упак. | AL12: ='[1]ЗАЯВКА-не смотрим!'!C39 -> шт. | AM12: ='[1]ЗАЯВКА-не смотрим!'!C40 -> упак. | AN12: ='[1]ЗАЯВКА-не смотрим!'!C41 -> упак. | AO12: ='[1]ЗАЯВКА-не смотрим!'!C42 -> шт. | AP12: ='[1]ЗАЯВКА-не смотрим!'!C43 -> шт. | AQ12: ='[1]ЗАЯВКА-не смотрим!'!C44 -> пач. | AR12: ='[1]ЗАЯВКА-не смотрим!'!C45 -> шт. | AS12: ='[1]ЗАЯВКА-не смотрим!'!C46 -> шт.
A13: 1 | B13: Ажнов Юрий Николаевич | C13: 2 | D13: 1 | E13: 1 | G13: 5 | H13: 1 | I13: 1 | K13: 1 | L13: 1 | M13: 1 | O13: 1 | P13: 1 | S13: 1 | U13: 1 | V13: 1 | Y13: 1 | AC13: 1 | AN13: 1
A14: 2 | B14: Айвазян Радик Христович | C14: 2 | D14: 1 | E14: 1 | G14: 5 | H14: 1 | I14: 1 | K14: 1 | L14: 1 | M14: 1 | O14: 1 | P14: 1 | S14: 1 | U14: 1 | V14: 1 | Y14: 1 | AC14: 1 | AN14: 1 | AQ14: 20
A15: 3 | B15: Артёмов Валерий Николаевич | C15: 2 | D15: 1 | E15: 1 | G15: 5 | H15: 1 | I15: 1 | K15: 1 | L15: 1 | M15: 1 | O15: 1 | P15: 1 | S15: 1 | U15: 1 | V15: 1 | Y15: 1 | AC15: 1 | AN15: 1
A16: 4 | B16: Алимов Андрей Анатольевич | C16: 2 | D16: 1 | E16: 1 | G16: 5 | H16: 1 | I16: 1 | K16: 1 | L16: 1 | M16: 1 | O16: 1 | P16: 1 | S16: 1 | U16: 1 | V16: 1 | Y16: 1 | AC16: 1 | AN16: 1 | AQ16: 20
A17: 5 | B17: Шаронов Леонид Иванович | C17: 2 | D17: 1 | E17: 1 | G17: 5 | H17: 1 | I17: 1 | K17: 1 | L17: 1 | M17: 1 | O17: 1 | P17: 1 | S17: 1 | U17: 1 | V17: 1 | Y17: 1 | AC17: 1 | AN17: 1
A18: 6 | B18: Байков Александр Владимирович | C18: 2 | D18: 1 | E18: 1 | G18: 5 | H18: 1 | I18: 1 | K18: 1 | L18: 1 | M18: 1 | O18: 1 | P18: 1 | S18: 1 | U18: 1 | V18: 1 | Y18: 1 | AC18: 1 | AN18: 1 | AQ18: 20
A19: 7 | B19: Григорьев Валерий Анатольевич | C19: 2 | D19: 1 | E19: 1 | G19: 5 | H19: 1 | I19: 1 | K19: 1 | L19: 1 | M19: 1 | O19: 1 | P19: 1 | S19: 1 | U19: 1 | V19: 1 | Y19: 1 | AC19: 1 | AN19: 1 | AQ19: 20
A20: 8 | B20: Данишкин Валерий Иванович | C20: 2 | D20: 1 | E20: 1 | G20: 5 | H20: 1 | I20: 1 | K20: 1 | L20: 1 | M20: 1 | O20: 1 | P20: 1 | S20: 1 | U20: 1 | V20: 1 | Y20: 1 | AC20: 1 | AN20: 1
A21: 9 | B21: Емельянов Виктор Николаевич | C21: 2 | D21: 1 | E21: 1 | G21: 5 | H21: 1 | I21: 1 | K21: 1 | L21: 1 | M21: 1 | O21: 1 | P21: 1 | S21: 1 | U21: 1 | V21: 1 | Y21: 1 | AC21: 1 | AN21: 1 | AQ21: 20
A22: 10 | B22: Кухов Олег Александрович | C22: 2 | D22: 1 | E22: 1 | G22: 5 | H22: 1 | I22: 1 | K22: 1 | L22: 1 | M22: 1 | O22: 1 | P22: 1 | S22: 1 | U22: 1 | V22: 1 | Y22: 1 | AC22: 1 | AN22: 1
A23: 11 | B23: Козлов Алексей Андреевич | C23: 2 | D23: 1 | E23: 1 | G23: 5 | H23: 1 | I23: 1 | K23: 1 | L23: 1 | M23: 1 | O23: 1 | P23: 1 | S23: 1 | U23: 1 | V23: 1 | Y23: 1 | AC23: 1 | AN23: 1 | AQ23: 20
A24: 12 | B24: Меньшов Василий Иванович | C24: 2 | D24: 1 | E24: 1 | G24: 5 | H24: 1 | I24: 1 | K24: 1 | L24: 1 | M24: 1 | O24: 1 | P24: 1 | S24: 1 | U24: 1 | V24: 1 | Y24: 1 | AC24: 1 | AN24: 1 | AQ24: 20
A25: 13 | B25: Марин Сергей Анатольевич | C25: 2 | D25: 1 | E25: 1 | G25: 5 | H25: 1 | I25: 1 | K25: 1 | L25: 1 | M25: 1 | O25: 1 | P25: 1 | S25: 1 | U25: 1 | V25: 1 | Y25: 1 | AC25: 1 | AN25: 1 | AQ25: 20
A26: 14 | B26: Наумов Виталий Николаевич | C26: 2 | D26: 1 | E26: 1 | G26: 5 | H26: 1 | I26: 1 | K26: 1 | L26: 1 | M26: 1 | O26: 1 | P26: 1 | S26: 1 | U26: 1 | V26: 1 | Y26: 1 | AC26: 1 | AN26: 1 | AQ26: 20
A27: 15 | B27: Пережогин Виталий Петрович | C27: 2 | D27: 1 | E27: 1 | G27: 5 | H27: 1 | I27: 1 | K27: 1 | L27: 1 | M27: 1 | O27: 1 | P27: 1 | S27: 1 | U27: 1 | V27: 1 | Y27: 1 | AC27: 1 | AN27: 1 | AQ27: 20
A28: 16 | B28: Потапов Петр Степанович | C28: 2 | D28: 1 | E28: 1 | G28: 5 | H28: 1 | I28: 1 | K28: 1 | L28: 1 | M28: 1 | O28: 1 | P28: 1 | S28: 1 | U28: 1 | V28: 1 | Y28: 1 | AC28: 1 | AN28: 1
A29: 17 | B29: Петросян Виктор Вартанович | C29: 2 | D29: 1 | E29: 1 | G29: 5 | H29: 1 | I29: 1 | K29: 1 | L29: 1 | M29: 1 | O29: 1 | P29: 1 | S29: 1 | U29: 1 | V29: 1 | Y29: 1 | AC29: 1 | AN29: 1
A30: 18 | B30: Путютин Борис Анатольевич | C30: 2 | D30: 1 | E30: 1 | G30: 5 | H30: 1 | I30: 1 | K30: 1 | L30: 1 | M30: 1 | O30: 1 | P30: 1 | S30: 1 | U30: 1 | V30: 1 | Y30: 1 | AC30: 1 | AN30: 1 | AQ30: 20
A31: 19 | B31: Ратников Михаил Александрович | C31: 2 | D31: 1 | E31: 1 | G31: 5 | H31: 1 | I31: 1 | K31: 1 | L31: 1 | M31: 1 | O31: 1 | P31: 1 | S31: 1 | U31: 1 | V31: 1 | Y31: 1 | AC31: 1 | AN31: 1 | AQ31: 20
A32: 20 | B32: Рыбчинский Василий Васильевич | C32: 2 | D32: 1 | E32: 1 | G32: 5 | H32: 1 | I32: 1 | K32: 1 | L32: 1 | M32: 1 | O32: 1 | P32: 1 | S32: 1 | U32: 1 | V32: 1 | Y32: 1 | AC32: 1 | AN32: 1 | AQ32: 20
A33: 21 | B33: Розмовенко Владислав Михайлович | C33: 2 | D33: 1 | E33: 1 | G33: 5 | H33: 1 | I33: 1 | K33: 1 | L33: 1 | M33: 1 | O33: 1 | P33: 1 | S33: 1 | U33: 1 | V33: 1 | Y33: 1 | AC33: 1 | AN33: 1
A34: 22 | B34: Ревдов Вячеслав Анатольевич | C34: 2 | D34: 1 | E34: 1 | G34: 5 | H34: 1 | I34: 1 | K34: 1 | L34: 1 | M34: 1 | O34: 1 | P34: 1 | S34: 1 | U34: 1 | V34: 1 | Y34: 1 | AC34: 1 | AN34: 1 | AQ34: 20
A35: 23 | B35: Степанов Дмитрий Алексеевич | C35: 2 | D35: 1 | E35: 1 | G35: 5 | H35: 1 | I35: 1 | K35: 1 | L35: 1 | M35: 1 | O35: 1 | P35: 1 | S35: 1 | U35: 1 | V35: 1 | Y35: 1 | AC35: 1 | AN35: 1 | AQ35: 20
A36: 24 | B36: Скляров Владимир Владимирович | C36: 2 | D36: 1 | E36: 1 | G36: 5 | H36: 1 | I36: 1 | K36: 1 | L36: 1 | M36: 1 | O36: 1 | P36: 1 | S36: 1 | U36: 1 | V36: 1 | Y36: 1 | AC36: 1 | AN36: 1 | AQ36: 20
A37: 25 | B37: Стульников Александр Сергеевич | C37: 2 | D37: 1 | E37: 1 | G37: 5 | H37: 1 | I37: 1 | K37: 1 | L37: 1 | M37: 1 | O37: 1 | P37: 1 | S37: 1 | U37: 1 | V37: 1 | Y37: 1 | AC37: 1 | AN37: 1 | AQ37: 20
A38: 26 | B38: Теплов Александр Иванович | C38: 2 | D38: 1 | E38: 1 | G38: 5 | H38: 1 | I38: 1 | K38: 1 | L38: 1 | M38: 1 | O38: 1 | P38: 1 | S38: 1 | U38: 1 | V38: 1 | Y38: 1 | AC38: 1 | AN38: 1 | AQ38: 20
A39: 27 | B39: Токарев Алексей Иванович | C39: 2 | D39: 1 | E39: 1 | G39: 5 | H39: 1 | I39: 1 | K39: 1 | L39: 1 | M39: 1 | O39: 1 | P39: 1 | S39: 1 | U39: 1 | V39: 1 | Y39: 1 | AC39: 1 | AN39: 1 | AQ39: 20
A40: 28 | B40: Трещев Николай Викторович | C40: 2 | D40: 1 | E40: 1 | G40: 5 | H40: 1 | I40: 1 | K40: 1 | L40: 1 | M40: 1 | O40: 1 | P40: 1 | S40: 1 | U40: 1 | V40: 1 | Y40: 1 | AC40: 1 | AN40: 1
A41: 29 | B41: Филин Сергей Николаевич | C41: 2 | D41: 1 | E41: 1 | G41: 5 | H41: 1 | I41: 1 | K41: 1 | L41: 1 | M41: 1 | O41: 1 | P41: 1 | S41: 1 | U41: 1 | V41: 1 | Y41: 1 | AC41: 1 | AN41: 1 | AQ41: 20
A42: 30 | B42: Чуйков Валерий Михайлович | C42: 2 | D42: 1 | E42: 1 | G42: 5 | H42: 1 | I42: 1 | K42: 1 | L42: 1 | M42: 1 | O42: 1 | P42: 1 | S42: 1 | U42: 1 | V42: 1 | Y42: 1 | AC42: 1 | AN42: 1 | AQ42: 20
A43: 31 | B43: Зайцев Сергей Николаевич | C43: 2 | D43: 1 | E43: 1 | G43: 5 | H43: 1 | I43: 1 | K43: 1 | L43: 1 | M43: 1 | O43: 1 | P43: 1 | S43: 1 | U43: 1 | V43: 1 | Y43: 1 | AC43: 1 | AN43: 1 | AQ43: 20
A44: 32 | B44: Войлочников Олег Викторович | C44: 2 | D44: 1 | E44: 1 | G44: 5 | H44: 1 | I44: 1 | K44: 1 | L44: 1 | M44: 1 | O44: 1 | P44: 1 | S44: 1 | U44: 1 | V44: 1 | Y44: 1 | AC44: 1 | AN44: 1
A45: 33 | B45: Дёмин Иван Андреевич | C45: 2 | D45: 1 | E45: 1 | G45: 5 | H45: 1 | I45: 1 | K45: 1 | L45: 1 | M45: 1 | O45: 1 | P45: 1 | S45: 1 | U45: 1 | V45: 1 | Y45: 1 | AC45: 1 | AN45: 1
A46: 34 | B46: Чопоров Николай Иванович | C46: 2 | D46: 1 | E46: 1 | G46: 5 | H46: 1 | I46: 1 | K46: 1 | L46: 1 | M46: 1 | O46: 1 | P46: 1 | S46: 1 | U46: 1 | V46: 1 | Y46: 1 | AC46: 1 | AN46: 1 | AQ46: 20
...

Sheet 1-С
A10: ЗАЯВКА
A11: на обеспечение продуктами питания и средствами личной гигиены за счет личных средств ПСУ отделения общего типа № 1
R12: на | S12: ='Справочник-не смотрим!'!B1 -> февраль | U12: ='Справочник-не смотрим!'!B2 -> 2026 | W12: года.
A14: № п/п | B14: ФИО | C14: Наименование товара
C15: ='Сводная ведомость'!D16 -> Вода питьевая негазир. (5 л.) | D15: ='Сводная ведомость'!E16 -> Туалетная бумага "Набережные Челны" (рул.) | E15: ='Сводная ведомость'!F16 -> Чай черный ГОСТ (100 гр.) | F15: ='Сводная ведомость'!G16 -> Чай черный пакетированный (25 пак.) | G15: ='Сводная ведомость'!H16 -> Станки для бритья "Джилет Blue II Maximum" однораз. | H15: ='Сводная ведомость'!I16 -> Говядина тушеная ж/б (325 гр. ключ) | I15: ='Сводная ведомость'!J16 -> Колбаса вареная "Докторская" ГОСТ (400 гр.) | J15: ='Сводная ведомость'!K16 -> Зефир Беково (белый, розовый, 250 гр.) | ... AS15: ='Сводная ведомость'!AT16 -> Зажигалка
C16: ='[1]ЗАЯВКА-не смотрим!'!C4 -> бут. | D16: ='[1]ЗАЯВКА-не смотрим!'!C5 -> шт. | E16: ='[1]ЗАЯВКА-не смотрим!'!C6 -> упак. | F16: ='[1]ЗАЯВКА-не смотрим!'!C7 -> упак. | G16: ='[1]ЗАЯВКА-не смотрим!'!C8 -> шт. | H16: ='[1]ЗАЯВКА-не смотрим!'!C9 -> шт. | I16: ='[1]ЗАЯВКА-не смотрим!'!C10 -> шт. | J16: ='[1]ЗАЯВКА-не смотрим!'!C11 -> упак. | K16: ='[1]ЗАЯВКА-не смотрим!'!C12 -> шт. | L16: ='[1]ЗАЯВКА-не смотрим!'!C13 -> шт. | M16: ='[1]ЗАЯВКА-не смотрим!'!C14 -> упак. | N16: ='[1]ЗАЯВКА-не смотрим!'!C15 -> шт. | O16: ='[1]ЗАЯВКА-не смотрим!'!C16 -> шт. | P16: ='[1]ЗАЯВКА-не смотрим!'!C17 -> шт. | Q16: ='[1]ЗАЯВКА-не смотрим!'!C18 -> шт. | R16: ='[1]ЗАЯВКА-не смотрим!'!C19 -> упак. | S16: ='[1]ЗАЯВКА-не смотрим!'!C20 -> упак. | T16: ='[1]ЗАЯВКА-не смотрим!'!C21 -> шт. | U16: ='[1]ЗАЯВКА-не смотрим!'!C22 -> упак. | V16: ='[1]ЗАЯВКА-не смотрим!'!C23 -> упак. | W16: ='[1]ЗАЯВКА-не смотрим!'!C24 -> шт. | X16: ='[1]ЗАЯВКА-не смотрим!'!C25 -> шт. | Y16: ='[1]ЗАЯВКА-не смотрим!'!C26 -> шт. | Z16: ='[1]ЗАЯВКА-не смотрим!'!C27 -> упак. | AA16: ='[1]ЗАЯВКА-не смотрим!'!C28 -> упак. | AB16: ='[1]ЗАЯВКА-не смотрим!'!C29 -> упак. | AC16: ='[1]ЗАЯВКА-не смотрим!'!C30 -> шт. | AD16: ='[1]ЗАЯВКА-не смотрим!'!C31 -> упак. | AE16: ='[1]ЗАЯВКА-не смотрим!'!C32 -> упак. | AF16: ='[1]ЗАЯВКА-не смотрим!'!C33 -> упак. | AG16: ='[1]ЗАЯВКА-не смотрим!'!C34 -> шт. | AH16: ='[1]ЗАЯВКА-не смотрим!'!C35 -> шт. | AI16: ='[1]ЗАЯВКА-не смотрим!'!C36 -> шт. | AJ16: ='[1]ЗАЯВКА-не смотрим!'!C37 -> шт. | AK16: ='[1]ЗАЯВКА-не смотрим!'!C38 -> упак. | AL16: ='[1]ЗАЯВКА-не смотрим!'!C39 -> шт. | AM16: ='[1]ЗАЯВКА-не смотрим!'!C40 -> упак. | AN16: ='[1]ЗАЯВКА-не смотрим!'!C41 -> упак. | AO16: ='[1]ЗАЯВКА-не смотрим!'!C42 -> шт. | AP16: ='[1]ЗАЯВКА-не смотрим!'!C43 -> шт. | AQ16: ='[1]ЗАЯВКА-не смотрим!'!C44 -> пач. | AR16: ='[1]ЗАЯВКА-не смотрим!'!C45 -> шт. | AS16: ='[1]ЗАЯВКА-не смотрим!'!C46 -> шт.
A17: 1 | B17: Демочкин Валерий Алексеевич | C17: 2 | D17: 1 | E17: 1 | G17: 5 | H17: 1 | I17: 1 | K17: 1 | L17: 1 | M17: 1 | P17: 1 | S17: 1 | Y17: 1 | AC17: 1 | AN17: 1 | AQ17: 10
A18: 2 | B18: Плеханов Вадим Викторович | C18: 2 | D18: 1 | E18: 1 | G18: 5 | H18: 1 | I18: 1 | K18: 1 | L18: 1 | M18: 1 | P18: 1 | S18: 1 | Y18: 1 | AC18: 1 | AN18: 1 | AQ18: 10
A19: 3 | B19: Туманов Виталий Михайлович | C19: 2 | D19: 1 | E19: 1 | G19: 5 | H19: 1 | I19: 1 | K19: 1 | L19: 1 | M19: 1 | P19: 1 | S19: 1 | Y19: 1 | AC19: 1 | AN19: 1
A20: 4 | B20: Маврин Александр Алексеевич | C20: 2 | D20: 1 | E20: 1 | G20: 5 | H20: 1 | I20: 1 | K20: 1 | L20: 1 | M20: 1 | P20: 1 | S20: 1 | Y20: 1 | AC20: 1 | AN20: 1 | AQ20: 10
A21: 5 | B21: Липин Василий Васильевич | C21: 2 | D21: 1 | E21: 1 | G21: 5 | H21: 1 | I21: 1 | K21: 1 | L21: 1 | M21: 1 | P21: 1 | S21: 1 | Y21: 1 | AC21: 1 | AN21: 1 | AQ21: 10
A22: 6 | B22: Худин Геннадий Александрович | C22: 2 | D22: 1 | E22: 1 | G22: 5 | H22: 1 | I22: 1 | K22: 1 | L22: 1 | M22: 1 | P22: 1 | S22: 1 | Y22: 1 | AC22: 1 | AN22: 1 | AQ22: 10
A23: 7 | B23: Шкренин Анатолий Дмитриевич | C23: 2 | D23: 1 | E23: 1 | G23: 5 | H23: 1 | I23: 1 | K23: 1 | L23: 1 | M23: 1 | P23: 1 | S23: 1 | Y23: 1 | AC23: 1 | AN23: 1
A24: 8 | B24: Вишняков Михаил Владимирович | C24: 2 | D24: 1 | E24: 1 | G24: 5 | H24: 1 | I24: 1 | K24: 1 | L24: 1 | M24: 1 | P24: 1 | S24: 1 | Y24: 1 | AC24: 1 | AN24: 1 | AQ24: 10
A25: 9 | B25: Малышев Михаил Александрович | C25: 2 | D25: 1 | E25: 1 | G25: 5 | H25: 1 | I25: 1 | K25: 1 | L25: 1 | M25: 1 | P25: 1 | S25: 1 | Y25: 1 | AC25: 1 | AN25: 1 | AQ25: 10
A26: 10 | B26: Горшунов Павел Владимирович | C26: 2 | D26: 1 | E26: 1 | G26: 5 | H26: 1 | I26: 1 | K26: 1 | L26: 1 | M26: 1 | P26: 1 | S26: 1 | Y26: 1 | AC26: 1 | AN26: 1 | AQ26: 10
A27: 11 | B27: Берестовой Эдуард Николаевич | C27: 2 | D27: 1 | E27: 1 | G27: 5 | H27: 1 | I27: 1 | K27: 1 | L27: 1 | M27: 1 | P27: 1 | S27: 1 | Y27: 1 | AC27: 1 | AN27: 1 | AQ27: 10
A28: 12 | B28: Арюткин Виталий Анатольевич | C28: 2 | D28: 1 | E28: 1 | G28: 5 | H28: 1 | I28: 1 | K28: 1 | L28: 1 | M28: 1 | P28: 1 | S28: 1 | Y28: 1 | AC28: 1 | AN28: 1 | AQ28: 10
A29: 13 | B29: Калтахчан Армен Фелекси | C29: 2 | D29: 1 | E29: 1 | G29: 5 | H29: 1 | I29: 1 | K29: 1 | L29: 1 | M29: 1 | P29: 1 | S29: 1 | Y29: 1 | AC29: 1 | AN29: 1 | AQ29: 10
A30: 14 | B30: Мартяхин Андрей Николаевич | C30: 2 | D30: 1 | E30: 1 | G30: 5 | H30: 1 | I30: 1 | K30: 1 | L30: 1 | M30: 1 | P30: 1 | S30: 1 | Y30: 1 | AC30: 1 | AN30: 1 | AQ30: 10
A31: 15 | B31: Трифонов Игорь Николаевич | C31: 2 | D31: 1 | E31: 1 | G31: 5 | H31: 1 | I31: 1 | K31: 1 | L31: 1 | M31: 1 | P31: 1 | S31: 1 | Y31: 1 | AC31: 1 | AN31: 1 | AQ31: 10
A32: 16 | B32: Белов Петр Игнатьевич | C32: 2 | D32: 1 | E32: 1 | G32: 5 | H32: 1 | I32: 1 | K32: 1 | L32: 1 | M32: 1 | P32: 1 | S32: 1 | Y32: 1 | AC32: 1 | AN32: 1 | AQ32: 10
A33: 17 | B33: Карпунин Юрий Степанович | C33: 2 | D33: 1 | E33: 1 | G33: 5 | H33: 1 | I33: 1 | K33: 1 | L33: 1 | M33: 1 | P33: 1 | S33: 1 | Y33: 1 | AC33: 1 | AN33: 1 | AQ33: 10
A34: 18 | B34: Кучин Алексей Николаевич | C34: 2 | D34: 1 | E34: 1 | G34: 5 | H34: 1 | I34: 1 | K34: 1 | L34: 1 | M34: 1 | P34: 1 | S34: 1 | Y34: 1 | AC34: 1 | AN34: 1 | AQ34: 10
A35: 19 | B35: Сосрокин Иван Петрович | C35: 2 | D35: 1 | E35: 1 | G35: 5 | H35: 1 | I35: 1 | K35: 1 | L35: 1 | M35: 1 | P35: 1 | S35: 1 | Y35: 1 | AC35: 1 | AN35: 1 | AQ35: 10
... A38: 22 | B38: Аббакумов Алексей Александрович | C38: 2 | D38: 1 | E38: 1 | G38: 5 | H38: 1 | I38: 1 | K38: 1 | L38: 1 | M38: 1 | P38: 1 | S38: 1 | Y38: 1 | AC38: 1 | AN38: 1 | AQ38: 10
A39: 23 | B39: Алиев Боговдин Омарович | C39: 2 | D39: 1 | E39: 1 | G39: 5 | H39: 1 | I39: 1 | K39: 1 | L39: 1 | M39: 1 | P39: 1 | S39: 1 | Y39: 1 | AC39: 1 | AN39: 1
A40: 24 | B40: Бочкарев Владимир Петрович | C40: 2 | D40: 1 | E40: 1 | G40: 5 | H40: 1 | I40: 1 | K40: 1 | L40: 1 | M40: 1 | P40: 1 | S40: 1 | Y40: 1 | AC40: 1 | AN40: 1 | AQ40: 10
A41: 25 | B41: Волков Вячеслав Иванович | C41: 2 | D41: 1 | E41: 1 | G41: 5 | H41: 1 | I41: 1 | K41: 1 | L41: 1 | M41: 1 | P41: 1 | S41: 1 | Y41: 1 | AC41: 1 | AN41: 1 | AQ41: 10
A42: 26 | B42: Голяков Владимир Иванович | C42: 2 | D42: 1 | E42: 1 | G42: 5 | H42: 1 | I42: 1 | K42: 1 | L42: 1 | M42: 1 | P42: 1 | S42: 1 | Y42: 1 | AC42: 1 | AN42: 1 | AQ42: 10
A43: 27 | B43: Калугин Владимир Викторович | C43: 2 | D43: 1 | E43: 1 | G43: 5 | H43: 1 | I43: 1 | K43: 1 | L43: 1 | M43: 1 | P43: 1 | S43: 1 | Y43: 1 | AC43: 1 | AN43: 1 | AQ43: 10
A44: 28 | B44: Курносов Александр Алексеевич | C44: 2 | D44: 1 | E44: 1 | G44: 5 | H44: 1 | I44: 1 | K44: 1 | L44: 1 | M44: 1 | P44: 1 | S44: 1 | Y44: 1 | AC44: 1 | AN44: 1 | AQ44: 10
A45: 29 | B45: Кузнецов Константин Викторович | C45: 2 | D45: 1 | E45: 1 | G45: 5 | H45: 1 | I45: 1 | K45: 1 | L45: 1 | M45: 1 | P45: 1 | S45: 1 | Y45: 1 | AC45: 1 | AN45: 1
A46: 30 | B46: Кузнецов Валерий Иванович | C46: 2 | D46: 1 | E46: 1 | G46: 5 | H46: 1 | I46: 1 | K46: 1 | L46: 1 | M46: 1 | P46: 1 | S46: 1 | Y46: 1 | AC46: 1 | AN46: 1 | AQ46: 10
A47: 31 | B47: Макрашин Михаил Дмитриевич | C47: 2 | D47: 1 | E47: 1 | G47: 5 | H47: 1 | I47: 1 | K47: 1 | L47: 1 | M47: 1 | P47: 1 | S47: 1 | Y47: 1 | AC47: 1 | AN47: 1 | AQ47: 10
A48: 32 | B48: Оськин Михаил Леонидович | C48: 2 | D48: 1 | E48: 1 | G48: 5 | H48: 1 | I48: 1 | K48: 1 | L48: 1 | M48: 1 | P48: 1 | S48: 1 | Y48: 1 | AC48: 1 | AN48: 1 | AQ48: 10
A49: 33 | B49: Полозов Александр Николаевич | C49: 2 | D49: 1 | E49: 1 | G49: 5 | H49: 1 | I49: 1 | K49: 1 | L49: 1 | M49: 1 | P49: 1 | S49: 1 | Y49: 1 | AC49: 1 | AN49: 1 | AQ49: 10
A50: 34 | B50: Спирин Виктор Борисович | C50: 2 | D50: 1 | E50: 1 | G50: 5 | H50: 1 | I50: 1 | K50: 1 | L50: 1 | M50: 1 | P50: 1 | S50: 1 | Y50: 1 | AC50: 1 | AN50: 1 | AQ50: 10
A51: 35 | B51: Свинухов Александр Николаевич | C51: 2 | D51: 1 | E51: 1 | G51: 5 | H51: 1 | I51: 1 | K51: 1 | L51: 1 | M51: 1 | P51: 1 | S51: 1 | Y51: 1 | AC51: 1 | AN51: 1 | AQ51: 10
A52: 36 | B52: Смирнов Владимир Александрович | C52: 2 | D52: 1 | E52: 1 | G52: 5 | H52: 1 | I52: 1 | K52: 1 | L52: 1 | M52: 1 | P52: 1 | S52: 1 | Y52: 1 | AC52: 1 | AN52: 1
...

Sheet 2-П
A10: ЗАЯВКА
A11: на обеспечение продуктами питания и средствами личной гигиены за счет личных средств ПСУ отделения общего типа № 2
R12: на | S12: ='Справочник-не смотрим!'!B1 -> февраль | U12: ='Справочник-не смотрим!'!B2 -> 2026 | W12: года.
A14: № п/п | B14: ФИО | C14: Наименование товара
C15: ='Сводная ведомость'!D16 -> Вода питьевая негазир. (5 л.) | D15: ='Сводная ведомость'!E16 -> Туалетная бумага "Набережные Челны" (рул.) | E15: ='Сводная ведомость'!F16 -> Чай черный ГОСТ (100 гр.) | F15: ='Сводная ведомость'!G16 -> Чай черный пакетированный (25 пак.) | G15: ='Сводная ведомость'!H16 -> Станки для бритья "Джилет Blue II Maximum" однораз. | H15: ='Сводная ведомость'!I16 -> Говядина тушеная ж/б (325 гр. ключ) | I15: ='Сводная ведомость'!J16 -> Колбаса вареная "Докторская" ГОСТ (400 гр.) | J15: ='Сводная ведомость'!K16 -> Зефир Беково (белый, розовый, 250 гр.) | ... AS15: ='Сводная ведомость'!AT16 -> Зажигалка
C16: ='ЗАЯВКА-не смотрим!'!C4 -> бут. | D16: ='ЗАЯВКА-не смотрим!'!C5 -> шт. | E16: ='ЗАЯВКА-не смотрим!'!C6 -> упак. | F16: ='ЗАЯВКА-не смотрим!'!C7 -> упак. | G16: ='ЗАЯВКА-не смотрим!'!C8 -> шт. | H16: ='ЗАЯВКА-не смотрим!'!C9 -> шт. | I16: ='ЗАЯВКА-не смотрим!'!C10 -> шт. | J16: ='ЗАЯВКА-не смотрим!'!C11 -> упак. | K16: ='ЗАЯВКА-не смотрим!'!C12 -> шт. | L16: ='ЗАЯВКА-не смотрим!'!C13 -> шт. | M16: ='ЗАЯВКА-не смотрим!'!C14 -> упак. | N16: ='ЗАЯВКА-не смотрим!'!C15 -> шт. | O16: ='ЗАЯВКА-не смотрим!'!C16 -> шт. | P16: ='ЗАЯВКА-не смотрим!'!C17 -> шт. | Q16: ='ЗАЯВКА-не смотрим!'!C18 -> шт. | R16: ='ЗАЯВКА-не смотрим!'!C19 -> упак. | S16: ='ЗАЯВКА-не смотрим!'!C20 -> упак. | T16: ='ЗАЯВКА-не смотрим!'!C21 -> шт. | U16: ='ЗАЯВКА-не смотрим!'!C22 -> упак. | V16: ='ЗАЯВКА-не смотрим!'!C23 -> упак. | W16: ='ЗАЯВКА-не смотрим!'!C24 -> шт. | X16: ='ЗАЯВКА-не смотрим!'!C25 -> шт. | Y16: ='ЗАЯВКА-не смотрим!'!C26 -> шт. | Z16: ='ЗАЯВКА-не смотрим!'!C27 -> упак. | AA16: ='ЗАЯВКА-не смотрим!'!C28 -> упак. | AB16: ='ЗАЯВКА-не смотрим!'!C29 -> упак. | AC16: ='ЗАЯВКА-не смотрим!'!C30 -> шт. | AD16: ='ЗАЯВКА-не смотрим!'!C31 -> упак. | AE16: ='ЗАЯВКА-не смотрим!'!C32 -> упак. | AF16: ='ЗАЯВКА-не смотрим!'!C33 -> упак. | AG16: ='ЗАЯВКА-не смотрим!'!C34 -> шт. | AH16: ='ЗАЯВКА-не смотрим!'!C35 -> шт. | AI16: ='ЗАЯВКА-не смотрим!'!C36 -> шт. | AJ16: ='ЗАЯВКА-не смотрим!'!C37 -> шт. | AK16: ='ЗАЯВКА-не смотрим!'!C38 -> упак. | AL16: ='ЗАЯВКА-не смотрим!'!C39 -> шт. | AM16: ='ЗАЯВКА-не смотрим!'!C40 -> упак. | AN16: ='ЗАЯВКА-не смотрим!'!C41 -> упак. | AO16: ='ЗАЯВКА-не смотрим!'!C42 -> шт. | AP16: ='ЗАЯВКА-не смотрим!'!C43 -> шт. | AQ16: ='ЗАЯВКА-не смотрим!'!C44 -> пач. | AR16: ='ЗАЯВКА-не смотрим!'!C45 -> шт. | AS16: ='ЗАЯВКА-не смотрим!'!C46 -> шт.
A17: 1 | B17: Алексеев Сергей Борисович | C17: 2 | D17: 1 | G17: 5 | H17: 1 | I17: 1 | K17: 1 | L17: 1 | M17: 1 | O17: 1 | P17: 1 | S17: 1 | U17: 1 | V17: 1 | Y17: 1 | AC17: 1 | AN17: 1
A18: 2 | B18: Алатырев Виктор Фёдорович | C18: 2 | D18: 1 | G18: 5 | H18: 1 | I18: 1 | K18: 1 | L18: 1 | M18: 1 | O18: 1 | P18: 1 | S18: 1 | U18: 1 | V18: 1 | Y18: 1 | AC18: 1 | AN18: 1
A19: 3 | B19: Батраков Владимир Анатольевич | C19: 2 | D19: 1 | G19: 5 | H19: 1 | I19: 1 | K19: 1 | L19: 1 | M19: 1 | O19: 1 | P19: 1 | S19: 1 | U19: 1 | V19: 1 | Y19: 1 | AC19: 1 | AN19: 1 | AQ19: 20
A20: 4 | B20: Белокуров Александр Владимирович | C20: 2 | D20: 1 | G20: 5 | H20: 1 | I20: 1 | K20: 1 | L20: 1 | M20: 1 | O20: 1 | P20: 1 | S20: 1 | U20: 1 | V20: 1 | Y20: 1 | AC20: 1 | AN20: 1
A21: 5 | B21: Беспалов Владимир Михайлович | C21: 2 | D21: 1 | G21: 5 | H21: 1 | I21: 1 | K21: 1 | L21: 1 | M21: 1 | O21: 1 | P21: 1 | S21: 1 | U21: 1 | V21: 1 | Y21: 1 | AC21: 1 | AN21: 1
A22: 6 | B22: Болдарев Сергей Викторович | C22: 2 | D22: 1 | G22: 5 | H22: 1 | I22: 1 | K22: 1 | L22: 1 | M22: 1 | O22: 1 | P22: 1 | S22: 1 | U22: 1 | V22: 1 | Y22: 1 | AC22: 1 | AN22: 1
A23: 7 | B23: Ванин Сергей Валерьевич | C23: 2 | D23: 1 | G23: 5 | H23: 1 | I23: 1 | K23: 1 | L23: 1 | M23: 1 | O23: 1 | P23: 1 | S23: 1 | U23: 1 | V23: 1 | Y23: 1 | AC23: 1 | AN23: 1
A24: 8 | B24: Лакехин Станислав Олегович | C24: 2 | D24: 1 | G24: 5 | H24: 1 | I24: 1 | K24: 1 | L24: 1 | M24: 1 | O24: 1 | P24: 1 | S24: 1 | U24: 1 | V24: 1 | Y24: 1 | AC24: 1 | AN24: 1
A25: 9 | B25: Дубровин Александр Егорович | C25: 2 | D25: 1 | G25: 5 | H25: 1 | I25: 1 | K25: 1 | L25: 1 | M25: 1 | O25: 1 | P25: 1 | S25: 1 | U25: 1 | V25: 1 | Y25: 1 | AC25: 1 | AN25: 1
A26: 10 | B26: Еремин Александр Борисович | C26: 2 | D26: 1 | G26: 5 | H26: 1 | I26: 1 | K26: 1 | L26: 1 | M26: 1 | O26: 1 | P26: 1 | S26: 1 | U26: 1 | V26: 1 | Y26: 1 | AC26: 1 | AN26: 1 | AQ26: 20
A27: 11 | B27: Емельянов Максим Сергеевич | C27: 2 | D27: 1 | G27: 5 | H27: 1 | I27: 1 | K27: 1 | L27: 1 | M27: 1 | O27: 1 | P27: 1 | S27: 1 | U27: 1 | V27: 1 | Y27: 1 | AC27: 1 | AN27: 1
A28: 12 | B28: Жидяев Анатолий Александрович | C28: 2 | D28: 1 | G28: 5 | H28: 1 | I28: 1 | K28: 1 | L28: 1 | M28: 1 | O28: 1 | P28: 1 | S28: 1 | U28: 1 | V28: 1 | Y28: 1 | AC28: 1 | AN28: 1 | AQ28: 20
A29: 13 | B29: Игонин Евгений Николаевич | C29: 2 | D29: 1 | G29: 5 | H29: 1 | I29: 1 | K29: 1 | L29: 1 | M29: 1 | O29: 1 | P29: 1 | S29: 1 | U29: 1 | V29: 1 | Y29: 1 | AC29: 1 | AN29: 1 | AQ29: 20
A30: 14 | B30: Киселев Михаил Иванович | C30: 2 | D30: 1 | G30: 5 | H30: 1 | I30: 1 | K30: 1 | L30: 1 | M30: 1 | O30: 1 | P30: 1 | S30: 1 | U30: 1 | V30: 1 | Y30: 1 | AC30: 1 | AN30: 1 | AQ30: 20
A31: 15 | B31: Климов Дмитрий Петрович | C31: 2 | D31: 1 | G31: 5 | H31: 1 | I31: 1 | K31: 1 | L31: 1 | M31: 1 | O31: 1 | P31: 1 | S31: 1 | U31: 1 | V31: 1 | Y31: 1 | AC31: 1 | AN31: 1
A32: 16 | B32: Коженков Юрий Анатольевич | C32: 2 | D32: 1 | G32: 5 | H32: 1 | I32: 1 | K32: 1 | L32: 1 | M32: 1 | O32: 1 | P32: 1 | S32: 1 | U32: 1 | V32: 1 | Y32: 1 | AC32: 1 | AN32: 1 | AQ32: 20
A33: 17 | B33: Кузин Вячеслав Петрович | C33: 2 | D33: 1 | G33: 5 | H33: 1 | I33: 1 | K33: 1 | L33: 1 | M33: 1 | O33: 1 | P33: 1 | S33: 1 | U33: 1 | V33: 1 | Y33: 1 | AC33: 1 | AN33: 1
A34: 18 | B34: Мальцев Борис Максимович | C34: 2 | D34: 1 | G34: 5 | H34: 1 | I34: 1 | K34: 1 | L34: 1 | M34: 1 | O34: 1 | P34: 1 | S34: 1 | U34: 1 | V34: 1 | Y34: 1 | AC34: 1 | AN34: 1
A35: 19 | B35: Миняев Виктор Васильевич | C35: 2 | D35: 1 | G35: 5 | H35: 1 | I35: 1 | K35: 1 | L35: 1 | M35: 1 | O35: 1 | P35: 1 | S35: 1 | U35: 1 | V35: 1 | Y35: 1 | AC35: 1 | AN35: 1
A36: 20 | B36: Митин Виктор Иванович | C36: 2 | D36: 1 | G36: 5 | H36: 1 | I36: 1 | K36: 1 | L36: 1 | M36: 1 | O36: 1 | P36: 1 | S36: 1 | U36: 1 | V36: 1 | Y36: 1 | AC36: 1 | AN36: 1
A37: 21 | B37: Моисеев Антон Васильевич | C37: 2 | D37: 1 | G37: 5 | H37: 1 | I37: 1 | K37: 1 | L37: 1 | M37: 1 | O37: 1 | P37: 1 | S37: 1 | U37: 1 | V37: 1 | Y37: 1 | AC37: 1 | AN37: 1 | AQ37: 20
A38: 22 | B38: Новиков Дмитрий Петрович | C38: 2 | D38: 1 | G38: 5 | H38: 1 | I38: 1 | K38: 1 | L38: 1 | M38: 1 | O38: 1 | P38: 1 | S38: 1 | U38: 1 | V38: 1 | Y38: 1 | AC38: 1 | AN38: 1
A39: 23 | B39: Остудин Василий Дмитриевич | C39: 2 | D39: 1 | G39: 5 | H39: 1 | I39: 1 | K39: 1 | L39: 1 | M39: 1 | O39: 1 | P39: 1 | S39: 1 | U39: 1 | V39: 1 | Y39: 1 | AC39: 1 | AN39: 1 | AQ39: 20
A40: 24 | B40: Поплевин Виктор Васильевич | C40: 2 | D40: 1 | G40: 5 | H40: 1 | I40: 1 | K40: 1 | L40: 1 | M40: 1 | O40: 1 | P40: 1 | S40: 1 | U40: 1 | V40: 1 | Y40: 1 | AC40: 1 | AN40: 1
A41: 25 | B41: Ревякин Александр Владимирович | C41: 2 | D41: 1 | G41: 5 | H41: 1 | I41: 1 | K41: 1 | L41: 1 | M41: 1 | O41: 1 | P41: 1 | S41: 1 | U41: 1 | V41: 1 | Y41: 1 | AC41: 1 | AN41: 1 | AQ41: 20
A42: 26 | B42: Рогожин Иван Васильевич | C42: 2 | D42: 1 | G42: 5 | H42: 1 | I42: 1 | K42: 1 | L42: 1 | M42: 1 | O42: 1 | P42: 1 | S42: 1 | U42: 1 | V42: 1 | Y42: 1 | AC42: 1 | AN42: 1
A43: 27 | B43: Рыжов Владимир Павлович | C43: 2 | D43: 1 | G43: 5 | H43: 1 | I43: 1 | K43: 1 | L43: 1 | M43: 1 | O43: 1 | P43: 1 | S43: 1 | U43: 1 | V43: 1 | Y43: 1 | AC43: 1 | AN43: 1
A44: 28 | B44: Савельев Вячеслав Николаевич | C44: 2 | D44: 1 | G44: 5 | H44: 1 | I44: 1 | K44: 1 | L44: 1 | M44: 1 | O44: 1 | P44: 1 | S44: 1 | U44: 1 | V44: 1 | Y44: 1 | AC44: 1 | AN44: 1
A45: 29 | B45: Селезнев Илья Алексеевич | C45: 2 | D45: 1 | G45: 5 | H45: 1 | I45: 1 | K45: 1 | L45: 1 | M45: 1 | O45: 1 | P45: 1 | S45: 1 | U45: 1 | V45: 1 | Y45: 1 | AC45: 1 | AN45: 1
A46: 30 | B46: Смирнов Алексей Анатольевич | C46: 2 | D46: 1 | G46: 5 | H46: 1 | I46: 1 | K46: 1 | L46: 1 | M46: 1 | O46: 1 | P46: 1 | S46: 1 | U46: 1 | V46: 1 | Y46: 1 | AC46: 1 | AN46: 1
A47: 31 | B47: Самойлов Андрей Александрович | C47: 2 | D47: 1 | G47: 5 | H47: 1 | I47: 1 | K47: 1 | L47: 1 | M47: 1 | O47: 1 | P47: 1 | S47: 1 | U47: 1 | V47: 1 | Y47: 1 | AC47: 1 | AN47: 1
A48: 32 | B48: Собачкин Юрий Георгиевич | C48: 2 | D48: 1 | G48: 5 | H48: 1 | I48: 1 | K48: 1 | L48: 1 | M48: 1 | O48: 1 | P48: 1 | S48: 1 | U48: 1 | V48: 1 | Y48: 1 | AC48: 1 | AN48: 1 | AQ48: 20
A49: 33 | B49: Саратовцев Михаил Юрьевич | C49: 2 | D49: 1 | G49: 5 | H49: 1 | I49: 1 | K49: 1 | L49: 1 | M49: 1 | O49: 1 | P49: 1 | S49: 1 | U49: 1 | V49: 1 | Y49: 1 | AC49: 1 | AN49: 1
A50: 34 | B50: Титкин Михаил Денисович | C50: 2 | D50: 1 | G50: 5 | H50: 1 | I50: 1 | K50: 1 | L50: 1 | M50: 1 | O50: 1 | P50: 1 | S50: 1 | U50: 1 | V50: 1 | Y50: 1 | AC50: 1 | AN50: 1
...

Sheet 2-С
A10: ЗАЯВКА
A11: на обеспечение продуктами питания и средствами личной гигиены за счет личных средств ПСУ отделения общего типа № 2
Q12: на | R12: ='Справочник-не смотрим!'!B1 -> февраль | T12: ='Справочник-не смотрим!'!B2 -> 2026 | V12: года.
A14: № п/п | B14: ФИО | C14: Наименование товара
C15: ='Сводная ведомость'!D16 -> Вода питьевая негазир. (5 л.) | D15: ='Сводная ведомость'!E16 -> Туалетная бумага "Набережные Челны" (рул.) | E15: ='Сводная ведомость'!F16 -> Чай черный ГОСТ (100 гр.) | F15: ='Сводная ведомость'!G16 -> Чай черный пакетированный (25 пак.) | G15: ='Сводная ведомость'!H16 -> Станки для бритья "Джилет Blue II Maximum" однораз. | H15: ='Сводная ведомость'!I16 -> Говядина тушеная ж/б (325 гр. ключ) | I15: ='Сводная ведомость'!J16 -> Колбаса вареная "Докторская" ГОСТ (400 гр.) | J15: ='Сводная ведомость'!K16 -> Зефир Беково (белый, розовый, 250 гр.) | ... AS15: ='Сводная ведомость'!AT16 -> Зажигалка
C16: ='ЗАЯВКА-не смотрим!'!C4 -> бут. | D16: ='ЗАЯВКА-не смотрим!'!C5 -> шт. | E16: ='ЗАЯВКА-не смотрим!'!C6 -> упак. | F16: ='ЗАЯВКА-не смотрим!'!C7 -> упак. | G16: ='ЗАЯВКА-не смотрим!'!C8 -> шт. | H16: ='ЗАЯВКА-не смотрим!'!C9 -> шт. | I16: ='ЗАЯВКА-не смотрим!'!C10 -> шт. | J16: ='ЗАЯВКА-не смотрим!'!C11 -> упак. | K16: ='ЗАЯВКА-не смотрим!'!C12 -> шт. | L16: ='ЗАЯВКА-не смотрим!'!C13 -> шт. | M16: ='ЗАЯВКА-не смотрим!'!C14 -> упак. | N16: ='ЗАЯВКА-не смотрим!'!C15 -> шт. | O16: ='ЗАЯВКА-не смотрим!'!C16 -> шт. | P16: ='ЗАЯВКА-не смотрим!'!C17 -> шт. | Q16: ='ЗАЯВКА-не смотрим!'!C18 -> шт. | R16: ='ЗАЯВКА-не смотрим!'!C19 -> упак. | S16: ='ЗАЯВКА-не смотрим!'!C20 -> упак. | T16: ='ЗАЯВКА-не смотрим!'!C21 -> шт. | U16: ='ЗАЯВКА-не смотрим!'!C22 -> упак. | V16: ='ЗАЯВКА-не смотрим!'!C23 -> упак. | W16: ='ЗАЯВКА-не смотрим!'!C24 -> шт. | X16: ='ЗАЯВКА-не смотрим!'!C25 -> шт. | Y16: ='ЗАЯВКА-не смотрим!'!C26 -> шт. | Z16: ='ЗАЯВКА-не смотрим!'!C27 -> упак. | AA16: ='ЗАЯВКА-не смотрим!'!C28 -> упак. | AB16: ='ЗАЯВКА-не смотрим!'!C29 -> упак. | AC16: ='ЗАЯВКА-не смотрим!'!C30 -> шт. | AD16: ='ЗАЯВКА-не смотрим!'!C31 -> упак. | AE16: ='ЗАЯВКА-не смотрим!'!C32 -> упак. | AF16: ='ЗАЯВКА-не смотрим!'!C33 -> упак. | AG16: ='ЗАЯВКА-не смотрим!'!C34 -> шт. | AH16: ='ЗАЯВКА-не смотрим!'!C35 -> шт. | AI16: ='ЗАЯВКА-не смотрим!'!C36 -> шт. | AJ16: ='ЗАЯВКА-не смотрим!'!C37 -> шт. | AK16: ='ЗАЯВКА-не смотрим!'!C38 -> упак. | AL16: ='ЗАЯВКА-не смотрим!'!C39 -> шт. | AM16: ='ЗАЯВКА-не смотрим!'!C40 -> упак. | AN16: ='ЗАЯВКА-не смотрим!'!C41 -> упак. | AO16: ='ЗАЯВКА-не смотрим!'!C42 -> шт. | AP16: ='ЗАЯВКА-не смотрим!'!C43 -> шт. | AQ16: ='ЗАЯВКА-не смотрим!'!C44 -> пач. | AR16: ='ЗАЯВКА-не смотрим!'!C45 -> шт. | AS16: ='ЗАЯВКА-не смотрим!'!C46 -> шт.
A17: 1 | B17: Гуськов Виктор Михайлович | C17: 2 | D17: 1 | G17: 5 | H17: 1 | I17: 1 | K17: 1 | L17: 1 | M17: 1 | P17: 1 | S17: 1 | Y17: 1 | AC17: 1 | AN17: 1 | AQ17: 10
A18: 2 | B18: Климов Александр Серегевич | C18: 2 | D18: 1 | G18: 5 | H18: 1 | I18: 1 | K18: 1 | L18: 1 | M18: 1 | P18: 1 | S18: 1 | Y18: 1 | AC18: 1 | AN18: 1 | AQ18: 10
A19: 3 | B19: Анохин Анатолий Павлович | C19: 2 | D19: 1 | G19: 5 | H19: 1 | I19: 1 | K19: 1 | L19: 1 | M19: 1 | P19: 1 | S19: 1 | Y19: 1 | AC19: 1 | AN19: 1 | AQ19: 10
A20: 4 | B20: Купранов Василий Васильевич | C20: 2 | D20: 1 | G20: 5 | H20: 1 | I20: 1 | K20: 1 | L20: 1 | M20: 1 | P20: 1 | S20: 1 | Y20: 1 | AC20: 1 | AN20: 1 | AQ20: 10
A21: 5 | B21: Самаров Василий Осипович | C21: 2 | D21: 1 | G21: 5 | H21: 1 | I21: 1 | K21: 1 | L21: 1 | M21: 1 | P21: 1 | S21: 1 | Y21: 1 | AC21: 1 | AN21: 1 | AQ21: 10
A22: 6 | B22: Синявский Александр Александрович | AQ22: 10
A23: 7 | B23: Куроносов Петр Васильевич | C23: 2 | D23: 1 | G23: 5 | H23: 1 | I23: 1 | K23: 1 | L23: 1 | M23: 1 | P23: 1 | S23: 1 | Y23: 1 | AC23: 1 | AN23: 1 | AQ23: 10
A24: 8 | B24: Баев Вячеслав Викторович | C24: 2 | D24: 1 | G24: 5 | H24: 1 | I24: 1 | K24: 1 | L24: 1 | M24: 1 | P24: 1 | S24: 1 | Y24: 1 | AC24: 1 | AN24: 1 | AQ24: 10
A25: 9 | B25: Баулин Михаил Владимирович | C25: 2 | D25: 1 | G25: 5 | H25: 1 | I25: 1 | K25: 1 | L25: 1 | M25: 1 | P25: 1 | S25: 1 | Y25: 1 | AC25: 1 | AN25: 1 | AQ25: 10
A26: 10 | B26: Бушмин Николай Алексеевич | C26: 2 | D26: 1 | G26: 5 | H26: 1 | I26: 1 | K26: 1 | L26: 1 | M26: 1 | P26: 1 | S26: 1 | Y26: 1 | AC26: 1 | AN26: 1 | AQ26: 10
A27: 11 | B27: Кукольников Владимир Александрович | C27: 2 | D27: 1 | G27: 5 | H27: 1 | I27: 1 | K27: 1 | L27: 1 | M27: 1 | P27: 1 | S27: 1 | Y27: 1 | AC27: 1 | AN27: 1
A28: 12 | B28: Любавин Владимир Петрович | C28: 2 | D28: 1 | G28: 5 | H28: 1 | I28: 1 | K28: 1 | L28: 1 | M28: 1 | P28: 1 | S28: 1 | Y28: 1 | AC28: 1 | AN28: 1
A29: 13 | B29: Дурнайкин Евгений Владимирович | C29: 2 | D29: 1 | G29: 5 | H29: 1 | I29: 1 | K29: 1 | L29: 1 | M29: 1 | P29: 1 | S29: 1 | Y29: 1 | AC29: 1 | AN29: 1 | AQ29: 10
A30: 14 | B30: Левин Сергей Николаевич | C30: 2 | D30: 1 | G30: 5 | H30: 1 | I30: 1 | K30: 1 | L30: 1 | M30: 1 | P30: 1 | S30: 1 | Y30: 1 | AC30: 1 | AN30: 1 | AQ30: 10
A31: 15 | B31: Левинский Петр Владимирович | C31: 2 | D31: 1 | G31: 5 | H31: 1 | I31: 1 | K31: 1 | L31: 1 | M31: 1 | P31: 1 | S31: 1 | Y31: 1 | AC31: 1 | AN31: 1 | AQ31: 10
A32: 16 | B32: Лысаков Сергей Викторович | C32: 2 | D32: 1 | G32: 5 | H32: 1 | I32: 1 | K32: 1 | L32: 1 | M32: 1 | P32: 1 | S32: 1 | Y32: 1 | AC32: 1 | AN32: 1 | AQ32: 10
A33: 17 | B33: Любера Петр Иванович | C33: 2 | D33: 1 | G33: 5 | H33: 1 | I33: 1 | K33: 1 | L33: 1 | M33: 1 | P33: 1 | S33: 1 | Y33: 1 | AC33: 1 | AN33: 1 | AQ33: 10
A34: 18 | B34: Мамедов Вивади Талжатович | C34: 2 | D34: 1 | G34: 5 | H34: 1 | I34: 1 | K34: 1 | L34: 1 | M34: 1 | P34: 1 | S34: 1 | Y34: 1 | AC34: 1 | AN34: 1 | AQ34: 10
A35: 19 | B35: Синебогов Александр Анатольевич | C35: 2 | D35: 1 | G35: 5 | H35: 1 | I35: 1 | K35: 1 | L35: 1 | M35: 1 | P35: 1 | S35: 1 | Y35: 1 | AC35: 1 | AN35: 1 | AQ35: 10
A36: 20 | B36: Карталев Александр Алексеевич | C36: 2 | D36: 1 | G36: 5 | H36: 1 | I36: 1 | K36: 1 | L36: 1 | M36: 1 | P36: 1 | S36: 1 | Y36: 1 | AC36: 1 | AN36: 1 | AQ36: 10
A37: 21 | B37: Шпильков Александр Германович | C37: 2 | D37: 1 | G37: 5 | H37: 1 | I37: 1 | K37: 1 | L37: 1 | M37: 1 | P37: 1 | S37: 1 | Y37: 1 | AC37: 1 | AN37: 1
A38: 22 | B38: Канцеров Борис Викторович | C38: 2 | D38: 1 | G38: 5 | H38: 1 | I38: 1 | K38: 1 | L38: 1 | M38: 1 | P38: 1 | S38: 1 | Y38: 1 | AC38: 1 | AN38: 1 | AQ38: 10
A39: 23 | B39: Грошев Александр Иванович | C39: 2 | D39: 1 | G39: 5 | H39: 1 | I39: 1 | K39: 1 | L39: 1 | M39: 1 | P39: 1 | S39: 1 | Y39: 1 | AC39: 1 | AN39: 1
A40: 24 | B40: Дергунов Александр Сергеевич | C40: 2 | D40: 1 | G40: 5 | H40: 1 | I40: 1 | K40: 1 | L40: 1 | M40: 1 | P40: 1 | S40: 1 | Y40: 1 | AC40: 1 | AN40: 1 | AQ40: 10
A41: 25 | B41: Исаев Кирилл Владимирович | C41: 2 | D41: 1 | G41: 5 | H41: 1 | I41: 1 | K41: 1 | L41: 1 | M41: 1 | P41: 1 | S41: 1 | Y41: 1 | AC41: 1 | AN41: 1 | AQ41: 10
A42: 26 | B42: Глусцов Александр Владимирович | C42: 2 | D42: 1 | G42: 5 | H42: 1 | I42: 1 | K42: 1 | L42: 1 | M42: 1 | P42: 1 | S42: 1 | Y42: 1 | AC42: 1 | AN42: 1
A43: 27 | B43: Пимкин Николай Иванович | C43: 2 | D43: 1 | G43: 5 | H43: 1 | I43: 1 | K43: 1 | L43: 1 | M43: 1 | P43: 1 | S43: 1 | Y43: 1 | AC43: 1 | AN43: 1 | AQ43: 10
A44: 28 | B44: Ромашин Олег Борисович | C44: 2 | D44: 1 | G44: 5 | H44: 1 | I44: 1 | K44: 1 | L44: 1 | M44: 1 | P44: 1 | S44: 1 | Y44: 1 | AC44: 1 | AN44: 1 | AQ44: 10
A45: 29 | B45: Славкин Алексей Петрович | C45: 2 | D45: 1 | G45: 5 | H45: 1 | I45: 1 | K45: 1 | L45: 1 | M45: 1 | P45: 1 | S45: 1 | Y45: 1 | AC45: 1 | AN45: 1 | AQ45: 10
A46: 30 | B46: Федякин Вячеслав Владимирович | C46: 2 | D46: 1 | G46: 5 | H46: 1 | I46: 1 | K46: 1 | L46: 1 | M46: 1 | P46: 1 | S46: 1 | Y46: 1 | AC46: 1 | AN46: 1 | AQ46: 10
A47: 31 | B47: Теплов Борис Александрович | C47: 2 | D47: 1 | G47: 5 | H47: 1 | I47: 1 | K47: 1 | L47: 1 | M47: 1 | P47: 1 | S47: 1 | Y47: 1 | AC47: 1 | AN47: 1 | AQ47: 10
B48: ИТОГО | C48: =SUM(C17:C47) -> 60 | D48: =SUM(D17:D47) -> 30 | E48: =SUM(E17:E47) -> 0 | F48: =SUM(F17:F47) -> 0 | G48: =SUM(G17:G47) -> 150 | H48: =SUM(H17:H47) -> 30 | I48: =SUM(I17:I47) -> 30 | J48: =SUM(J17:J47) -> 0 | ... AS48: =SUM(AS17:AS47) -> 0
B52: Составил | C52: член опекунской комиссии
K53: подпись | U53: фио

Sheet 2-СД
A10: ЗАЯВКА
A11: на обеспечение продуктами питания и средствами личной гигиены за счет личных средств ПСУ отделения общего типа № 2
S12: на | T12: ='Справочник-не смотрим!'!B1 -> февраль | V12: ='Справочник-не смотрим!'!B2 -> 2026 | X12: года.
A14: № п/п | B14: ФИО | C14: Наименование товара
C15: ='Сводная ведомость'!D16 -> Вода питьевая негазир. (5 л.) | D15: ='Сводная ведомость'!E16 -> Туалетная бумага "Набережные Челны" (рул.) | E15: ='Сводная ведомость'!F16 -> Чай черный ГОСТ (100 гр.) | F15: ='Сводная ведомость'!G16 -> Чай черный пакетированный (25 пак.) | G15: ='Сводная ведомость'!H16 -> Станки для бритья "Джилет Blue II Maximum" однораз. | H15: ='Сводная ведомость'!I16 -> Говядина тушеная ж/б (325 гр. ключ) | I15: ='Сводная ведомость'!J16 -> Колбаса вареная "Докторская" ГОСТ (400 гр.) | J15: ='Сводная ведомость'!K16 -> Зефир Беково (белый, розовый, 250 гр.) | ... AS15: ='Сводная ведомость'!AT16 -> Зажигалка
C16: ='ЗАЯВКА-не смотрим!'!C4 -> бут. | D16: ='ЗАЯВКА-не смотрим!'!C5 -> шт. | E16: ='ЗАЯВКА-не смотрим!'!C6 -> упак. | F16: ='ЗАЯВКА-не смотрим!'!C7 -> упак. | G16: ='ЗАЯВКА-не смотрим!'!C8 -> шт. | H16: ='ЗАЯВКА-не смотрим!'!C9 -> шт. | I16: ='ЗАЯВКА-не смотрим!'!C10 -> шт. | J16: ='ЗАЯВКА-не смотрим!'!C11 -> упак. | K16: ='ЗАЯВКА-не смотрим!'!C12 -> шт. | L16: ='ЗАЯВКА-не смотрим!'!C13 -> шт. | M16: ='ЗАЯВКА-не смотрим!'!C14 -> упак. | N16: ='ЗАЯВКА-не смотрим!'!C15 -> шт. | O16: ='ЗАЯВКА-не смотрим!'!C16 -> шт. | P16: ='ЗАЯВКА-не смотрим!'!C17 -> шт. | Q16: ='ЗАЯВКА-не смотрим!'!C18 -> шт. | R16: ='ЗАЯВКА-не смотрим!'!C19 -> упак. | S16: ='ЗАЯВКА-не смотрим!'!C20 -> упак. | T16: ='ЗАЯВКА-не смотрим!'!C21 -> шт. | U16: ='ЗАЯВКА-не смотрим!'!C22 -> упак. | V16: ='ЗАЯВКА-не смотрим!'!C23 -> упак. | W16: ='ЗАЯВКА-не смотрим!'!C24 -> шт. | X16: ='ЗАЯВКА-не смотрим!'!C25 -> шт. | Y16: ='ЗАЯВКА-не смотрим!'!C26 -> шт. | Z16: ='ЗАЯВКА-не смотрим!'!C27 -> упак. | AA16: ='ЗАЯВКА-не смотрим!'!C28 -> упак. | AB16: ='ЗАЯВКА-не смотрим!'!C29 -> упак. | AC16: ='ЗАЯВКА-не смотрим!'!C30 -> шт. | AD16: ='ЗАЯВКА-не смотрим!'!C31 -> упак. | AE16: ='ЗАЯВКА-не смотрим!'!C32 -> упак. | AF16: ='ЗАЯВКА-не смотрим!'!C33 -> упак. | AG16: ='ЗАЯВКА-не смотрим!'!C34 -> шт. | AH16: ='ЗАЯВКА-не смотрим!'!C35 -> шт. | AI16: ='ЗАЯВКА-не смотрим!'!C36 -> шт. | AJ16: ='ЗАЯВКА-не смотрим!'!C37 -> шт. | AK16: ='ЗАЯВКА-не смотрим!'!C38 -> упак. | AL16: ='ЗАЯВКА-не смотрим!'!C39 -> шт. | AM16: ='ЗАЯВКА-не смотрим!'!C40 -> упак. | AN16: ='ЗАЯВКА-не смотрим!'!C41 -> упак. | AO16: ='ЗАЯВКА-не смотрим!'!C42 -> шт. | AP16: ='ЗАЯВКА-не смотрим!'!C43 -> шт. | AQ16: ='ЗАЯВКА-не смотрим!'!C44 -> пач. | AR16: ='ЗАЯВКА-не смотрим!'!C45 -> шт. | AS16: ='ЗАЯВКА-не смотрим!'!C46 -> шт.
A17: 1 | B17: Дажин Александр Серафимович | C17: 2 | D17: 1 | G17: 5 | H17: 1 | I17: 1 | K17: 1 | L17: 1 | Y17: 1 | Z17: 1 | AA17: 1 | AB17: 1 | AC17: 1 | AD17: 1 | AE17: 1
A18: 2 | B18: Осин Николай Иванович | C18: 2 | D18: 1 | G18: 5 | H18: 1 | I18: 1 | K18: 1 | L18: 1 | Y18: 1 | Z18: 1 | AA18: 1 | AB18: 1 | AC18: 1 | AD18: 1 | AE18: 1
A19: 3 | B19: Суханов Игорь Анатольевич | C19: 2 | D19: 1 | G19: 5 | H19: 1 | I19: 1 | K19: 1 | L19: 1 | Y19: 1 | Z19: 1 | AA19: 1 | AB19: 1 | AC19: 1 | AD19: 1 | AE19: 1 | AQ19: 10
B20: ИТОГО | C20: =C17+C18+C19 -> 6 | D20: =D17+D18+D19 -> 3 | E20: =E17+E18+E19 -> 0 | F20: =F17+F18+F19 -> 0 | G20: =G17+G18+G19 -> 15 | H20: =H17+H18+H19 -> 3 | I20: =I17+I18+I19 -> 3 | J20: =J17+J18+J19 -> 0 | ... AS20: =AS17+AS18+AS19 -> 0
B24: Составил | C24: член опекунской комиссии
K25: подпись | U25: фио

Sheet 3-П
A10: ЗАЯВКА
A11: на обеспечение продуктами питания и средствами личной гигиены за счет личных средств ПСУ отделения общего типа № 3
Q12: на | R12: ='Справочник-не смотрим!'!B1 -> февраль | T12: ='Справочник-не смотрим!'!B2 -> 2026 | V12: года.
A14: № п/п | B14: ФИО | C14: Наименование товара
C15: ='Сводная ведомость'!D16 -> Вода питьевая негазир. (5 л.) | D15: ='Сводная ведомость'!E16 -> Туалетная бумага "Набережные Челны" (рул.) | E15: ='Сводная ведомость'!F16 -> Чай черный ГОСТ (100 гр.) | F15: ='Сводная ведомость'!G16 -> Чай черный пакетированный (25 пак.) | G15: ='Сводная ведомость'!H16 -> Станки для бритья "Джилет Blue II Maximum" однораз. | H15: ='Сводная ведомость'!I16 -> Говядина тушеная ж/б (325 гр. ключ) | I15: ='Сводная ведомость'!J16 -> Колбаса вареная "Докторская" ГОСТ (400 гр.) | J15: ='Сводная ведомость'!K16 -> Зефир Беково (белый, розовый, 250 гр.) | ... AS15: ='Сводная ведомость'!AT16 -> Зажигалка
